Workbook

Sheet 26년 1월 유효회원
A1: .
B2: 1월 | C2: 유효회원 | D2: 남 | E2: 여 | F2: 만료회원 | G2: 남 | H2: 여
C3: =COUNTIF($K:$K,"유효") -> 159 | D3: =COUNTIFS($K:$K,"유효",$C:$C,"남") -> 33 | E3: =COUNTIFS($K:$K,"유효",$C:$C,"여") -> 126 | F3: =COUNTIF($L:$L,"만료") -> 5 | G3: =COUNTIFS($L:$L,"만료",$C:$C,"남") -> 1 | H3: =COUNTIFS($L:$L,"만료",$C:$C,"여") -> 4
K4: 46023 | L4: 46053
B5: 이름 | C5: 성별 | D5: 전화번호 | E5: 등록 개월 | F5: 접수일 | G5: 시작일 | H5: 종료일 | I5: 출석수 | J5: 출석률 | K5: 유효회원 | L5: 만료회원 | M5: 배정선생님 | N5: 피트릭스 | O5: 인바디 | P5: 1주차 | R5: 2주차 | T5: 3주차 | V5: 4주차 | X5: 5주차
B6: 김정숙 | C6: 여 | D6: 010-7197-6510 | E6: FPT 6개월 | F6: 45834 | G6: 45859 | H6: 46112 | I6: =VLOOKUP(B6,'26년 1월 출석표'!$B$7:$D$500,3,0) -> 2 | J6: =ifna(I6/21,0) -> #NAME? | K6: =IF(AND(G6<=$L$4,H6>=$K$4),"유효","") -> 유효 | L6: =IF(AND(H6>=$K$4,H6<=$L$4),"만료","") | N6: FALSE | O6: FALSE | P6: =VLOOKUP($B6,'26년 1월 출석표'!$B$2:$BQ$497,10,0)/1 -> 0 | R6: =VLOOKUP($B6,'26년 1월 출석표'!$B$2:$BQ$497,24,0)/5 -> 0.4 | T6: =VLOOKUP($B6,'26년 1월 출석표'!$B$2:$BQ$497,38,0)/5 -> 0 | V6: =VLOOKUP($B6,'26년 1월 출석표'!$B$2:$BQ$497,52,0)/5 -> 0 | X6: =VLOOKUP($B6,'26년 1월 출석표'!$B$2:$BQ$503,66,0)/5 -> 0
B7: 신하영 | C7: 여 | D7: 010-7406-1778 | E7: FPT 6개월 | F7: 45834 | G7: 45951 | H7: 46192 | I7: =VLOOKUP(B7,'26년 1월 출석표'!$B$7:$D$500,3,0) -> 0 | J7: =ifna(I7/21,0) -> #NAME? | K7: =IF(AND(G7<=$L$4,H7>=$K$4),"유효","") -> 유효 | L7: =IF(AND(H7>=$K$4,H7<=$L$4),"만료","") | N7: FALSE | O7: FALSE | P7: =VLOOKUP($B7,'26년 1월 출석표'!$B$2:$BQ$497,10,0)/1 -> 0 | R7: =VLOOKUP($B7,'26년 1월 출석표'!$B$2:$BQ$497,24,0)/5 -> 0 | T7: =VLOOKUP($B7,'26년 1월 출석표'!$B$2:$BQ$497,38,0)/5 -> 0 | V7: =VLOOKUP($B7,'26년 1월 출석표'!$B$2:$BQ$497,52,0)/5 -> 0 | X7: =VLOOKUP($B7,'26년 1월 출석표'!$B$2:$BQ$503,66,0)/5 -> 0
B8: 정지우 | C8: 여 | D8: 010-4703-7598 | E8: FPT 9개월 | F8: 45834 | G8: 45962 | H8: 46249 | I8: =VLOOKUP(B8,'26년 1월 출석표'!$B$7:$D$500,3,0) -> 3 | J8: =ifna(I8/21,0) -> #NAME? | K8: =IF(AND(G8<=$L$4,H8>=$K$4),"유효","") -> 유효 | L8: =IF(AND(H8>=$K$4,H8<=$L$4),"만료","") | N8: TRUE | O8: TRUE | P8: =VLOOKUP($B8,'26년 1월 출석표'!$B$2:$BQ$497,10,0)/1 -> 0 | R8: =VLOOKUP($B8,'26년 1월 출석표'!$B$2:$BQ$497,24,0)/5 -> 0.6 | T8: =VLOOKUP($B8,'26년 1월 출석표'!$B$2:$BQ$497,38,0)/5 -> 0 | V8: =VLOOKUP($B8,'26년 1월 출석표'!$B$2:$BQ$497,52,0)/5 -> 0 | X8: =VLOOKUP($B8,'26년 1월 출석표'!$B$2:$BQ$503,66,0)/5 -> 0
B9: 곽상희 | C9: 여 | D9: 010-8751-6220 | E9: FPT 12개월 | F9: 45835 | G9: 45859 | H9: 46223 | I9: =VLOOKUP(B9,'26년 1월 출석표'!$B$7:$D$500,3,0) -> 0 | J9: =ifna(I9/21,0) -> #NAME? | K9: =IF(AND(G9<=$L$4,H9>=$K$4),"유효","") -> 유효 | L9: =IF(AND(H9>=$K$4,H9<=$L$4),"만료","") | N9: FALSE | O9: FALSE | P9: =VLOOKUP($B9,'26년 1월 출석표'!$B$2:$BQ$497,10,0)/1 -> 0 | R9: =VLOOKUP($B9,'26년 1월 출석표'!$B$2:$BQ$497,24,0)/5 -> 0 | T9: =VLOOKUP($B9,'26년 1월 출석표'!$B$2:$BQ$497,38,0)/5 -> 0 | V9: =VLOOKUP($B9,'26년 1월 출석표'!$B$2:$BQ$497,52,0)/5 -> 0 | X9: =VLOOKUP($B9,'26년 1월 출석표'!$B$2:$BQ$503,66,0)/5 -> 0
B10: 임성빈 | C10: 남 | D10: 010-5238-4621 | E10: FPT 12개월 | F10: 45835 | G10: 45859 | H10: 46223 | I10: =VLOOKUP(B10,'26년 1월 출석표'!$B$7:$D$500,3,0) -> 0 | J10: =ifna(I10/21,0) -> #NAME? | K10: =IF(AND(G10<=$L$4,H10>=$K$4),"유효","") -> 유효 | L10: =IF(AND(H10>=$K$4,H10<=$L$4),"만료","") | N10: FALSE | O10: FALSE | P10: =VLOOKUP($B10,'26년 1월 출석표'!$B$2:$BQ$497,10,0)/1 -> 0 | R10: =VLOOKUP($B10,'26년 1월 출석표'!$B$2:$BQ$497,24,0)/5 -> 0 | T10: =VLOOKUP($B10,'26년 1월 출석표'!$B$2:$BQ$497,38,0)/5 -> 0 | V10: =VLOOKUP($B10,'26년 1월 출석표'!$B$2:$BQ$497,52,0)/5 -> 0 | X10: =VLOOKUP($B10,'26년 1월 출석표'!$B$2:$BQ$503,66,0)/5 -> 0
B11: 이난영 | C11: 여 | D11: 010-5673-8991 | E11: FPT 6개월 | F11: 45838 | G11: 45859 | H11: 46132 | I11: =VLOOKUP(B11,'26년 1월 출석표'!$B$7:$D$500,3,0) -> 0 | J11: =ifna(I11/21,0) -> #NAME? | K11: =IF(AND(G11<=$L$4,H11>=$K$4),"유효","") -> 유효 | L11: =IF(AND(H11>=$K$4,H11<=$L$4),"만료","") | N11: FALSE | O11: FALSE | P11: =VLOOKUP($B11,'26년 1월 출석표'!$B$2:$BQ$497,10,0)/1 -> 0 | R11: =VLOOKUP($B11,'26년 1월 출석표'!$B$2:$BQ$497,24,0)/5 -> 0 | T11: =VLOOKUP($B11,'26년 1월 출석표'!$B$2:$BQ$497,38,0)/5 -> 0 | V11: =VLOOKUP($B11,'26년 1월 출석표'!$B$2:$BQ$497,52,0)/5 -> 0 | X11: =VLOOKUP($B11,'26년 1월 출석표'!$B$2:$BQ$503,66,0)/5 -> 0
B12: 이지현 | C12: 여 | D12: 010-9077-6644 | E12: FPT 12개월 | F12: 45838 | G12: 45859 | H12: 46268 | I12: =VLOOKUP(B12,'26년 1월 출석표'!$B$7:$D$500,3,0) -> 2 | J12: =ifna(I12/21,0) -> #NAME? | K12: =IF(AND(G12<=$L$4,H12>=$K$4),"유효","") -> 유효 | L12: =IF(AND(H12>=$K$4,H12<=$L$4),"만료","") | N12: FALSE | O12: FALSE | P12: =VLOOKUP($B12,'26년 1월 출석표'!$B$2:$BQ$497,10,0)/1 -> 0 | R12: =VLOOKUP($B12,'26년 1월 출석표'!$B$2:$BQ$497,24,0)/5 -> 0.4 | T12: =VLOOKUP($B12,'26년 1월 출석표'!$B$2:$BQ$497,38,0)/5 -> 0 | V12: =VLOOKUP($B12,'26년 1월 출석표'!$B$2:$BQ$497,52,0)/5 -> 0 | X12: =VLOOKUP($B12,'26년 1월 출석표'!$B$2:$BQ$503,66,0)/5 -> 0
B13: 정유찬 | C13: 남 | D13: 010-5923-3791 | E13: FPT 6개월 | F13: 45839 | G13: 45859 | H13: 46057 | I13: =VLOOKUP(B13,'26년 1월 출석표'!$B$7:$D$500,3,0) -> 4 | J13: =ifna(I13/21,0) -> #NAME? | K13: =IF(AND(G13<=$L$4,H13>=$K$4),"유효","") -> 유효 | L13: =IF(AND(H13>=$K$4,H13<=$L$4),"만료","") | N13: FALSE | O13: FALSE | P13: =VLOOKUP($B13,'26년 1월 출석표'!$B$2:$BQ$497,10,0)/1 -> 0 | R13: =VLOOKUP($B13,'26년 1월 출석표'!$B$2:$BQ$497,24,0)/5 -> 0.6 | T13: =VLOOKUP($B13,'26년 1월 출석표'!$B$2:$BQ$497,38,0)/5 -> 0.2 | V13: =VLOOKUP($B13,'26년 1월 출석표'!$B$2:$BQ$497,52,0)/5 -> 0 | X13: =VLOOKUP($B13,'26년 1월 출석표'!$B$2:$BQ$503,66,0)/5 -> 0
B14: 전용순 | C14: 여 | D14: 010-8983-3271 | E14: FPT 12개월 | F14: 45839 | G14: 45859 | H14: 46223 | I14: =VLOOKUP(B14,'26년 1월 출석표'!$B$7:$D$500,3,0) -> 6 | J14: =ifna(I14/21,0) -> #NAME? | K14: =IF(AND(G14<=$L$4,H14>=$K$4),"유효","") -> 유효 | L14: =IF(AND(H14>=$K$4,H14<=$L$4),"만료","") | N14: FALSE | O14: FALSE | P14: =VLOOKUP($B14,'26년 1월 출석표'!$B$2:$BQ$497,10,0)/1 -> 1 | R14: =VLOOKUP($B14,'26년 1월 출석표'!$B$2:$BQ$497,24,0)/5 -> 0.8 | T14: =VLOOKUP($B14,'26년 1월 출석표'!$B$2:$BQ$497,38,0)/5 -> 0.2 | V14: =VLOOKUP($B14,'26년 1월 출석표'!$B$2:$BQ$497,52,0)/5 -> 0 | X14: =VLOOKUP($B14,'26년 1월 출석표'!$B$2:$BQ$503,66,0)/5 -> 0
B15: 김용희 | C15: 남 | D15: 010-2950-3381 | E15: FPT 6개월 | F15: 45839 | G15: 45875 | H15: 46239 | I15: =VLOOKUP(B15,'26년 1월 출석표'!$B$7:$D$500,3,0) -> 1 | J15: =ifna(I15/21,0) -> #NAME? | K15: =IF(AND(G15<=$L$4,H15>=$K$4),"유효","") -> 유효 | L15: =IF(AND(H15>=$K$4,H15<=$L$4),"만료","") | N15: FALSE | O15: FALSE | P15: =VLOOKUP($B15,'26년 1월 출석표'!$B$2:$BQ$497,10,0)/1 -> 0 | R15: =VLOOKUP($B15,'26년 1월 출석표'!$B$2:$BQ$497,24,0)/5 -> 0.2 | T15: =VLOOKUP($B15,'26년 1월 출석표'!$B$2:$BQ$497,38,0)/5 -> 0 | V15: =VLOOKUP($B15,'26년 1월 출석표'!$B$2:$BQ$497,52,0)/5 -> 0 | X15: =VLOOKUP($B15,'26년 1월 출석표'!$B$2:$BQ$503,66,0)/5 -> 0
B16: 황서영 | C16: 여 | D16: 010-5457-5827 | E16: FPT 12개월 | F16: 45839 | G16: 45859 | H16: 46240 | I16: =VLOOKUP(B16,'26년 1월 출석표'!$B$7:$D$500,3,0) -> 6 | J16: =ifna(I16/21,0) -> #NAME? | K16: =IF(AND(G16<=$L$4,H16>=$K$4),"유효","") -> 유효 | L16: =IF(AND(H16>=$K$4,H16<=$L$4),"만료","") | N16: FALSE | O16: FALSE | P16: =VLOOKUP($B16,'26년 1월 출석표'!$B$2:$BQ$497,10,0)/1 -> 1 | R16: =VLOOKUP($B16,'26년 1월 출석표'!$B$2:$BQ$497,24,0)/5 -> 0.8 | T16: =VLOOKUP($B16,'26년 1월 출석표'!$B$2:$BQ$497,38,0)/5 -> 0.2 | V16: =VLOOKUP($B16,'26년 1월 출석표'!$B$2:$BQ$497,52,0)/5 -> 0 | X16: =VLOOKUP($B16,'26년 1월 출석표'!$B$2:$BQ$503,66,0)/5 -> 0
B17: 박유나 | C17: 여 | D17: 010-2949-9347 | E17: FPT 9개월 | F17: 45839 | G17: 45859 | H17: 46300 | I17: =VLOOKUP(B17,'26년 1월 출석표'!$B$7:$D$500,3,0) -> 1 | J17: =ifna(I17/21,0) -> #NAME? | K17: =IF(AND(G17<=$L$4,H17>=$K$4),"유효","") -> 유효 | L17: =IF(AND(H17>=$K$4,H17<=$L$4),"만료","") | N17: FALSE | O17: FALSE | P17: =VLOOKUP($B17,'26년 1월 출석표'!$B$2:$BQ$497,10,0)/1 -> 0 | R17: =VLOOKUP($B17,'26년 1월 출석표'!$B$2:$BQ$497,24,0)/5 -> 0 | T17: =VLOOKUP($B17,'26년 1월 출석표'!$B$2:$BQ$497,38,0)/5 -> 0.2 | V17: =VLOOKUP($B17,'26년 1월 출석표'!$B$2:$BQ$497,52,0)/5 -> 0 | X17: =VLOOKUP($B17,'26년 1월 출석표'!$B$2:$BQ$503,66,0)/5 -> 0
... B149: 김혜경 | C149: 여 | D149: 010-4706-6876 | E149: FPT 9개월 | F149: 46018 | G149: 46023 | H149: 46385 | I149: =VLOOKUP(B149,'26년 1월 출석표'!$B$7:$D$500,3,0) -> 1 | J149: =ifna(I149/21,0) -> #NAME? | K149: =IF(AND(G149<=$L$4,H149>=$K$4),"유효","") -> 유효 | L149: =IF(AND(H149>=$K$4,H149<=$L$4),"만료","") | N149: FALSE | O149: FALSE | P149: =VLOOKUP($B149,'26년 1월 출석표'!$B$2:$BQ$497,10,0)/1 -> 0 | R149: =VLOOKUP($B149,'26년 1월 출석표'!$B$2:$BQ$497,24,0)/5 -> 0.2 | T149: =VLOOKUP($B149,'26년 1월 출석표'!$B$2:$BQ$497,38,0)/5 -> 0 | V149: =VLOOKUP($B149,'26년 1월 출석표'!$B$2:$BQ$497,52,0)/5 -> 0 | X149: =VLOOKUP($B149,'26년 1월 출석표'!$B$2:$BQ$503,66,0)/5 -> 0
B150: 이소윤 | C150: 여 | D150: 010-2627-9028 | E150: FPT 횟수권 | F150: 46018 | G150: 46018 | H150: - | I150: =VLOOKUP(B150,'26년 1월 출석표'!$B$7:$D$500,3,0) -> 0 | J150: =ifna(I150/21,0) -> #NAME? | K150: =IF(AND(G150<=$L$4,H150>=$K$4),"유효","") -> 유효 | L150: =IF(AND(H150>=$K$4,H150<=$L$4),"만료","") | N150: FALSE | O150: FALSE | P150: =VLOOKUP($B150,'26년 1월 출석표'!$B$2:$BQ$497,10,0)/1 -> 0 | R150: =VLOOKUP($B150,'26년 1월 출석표'!$B$2:$BQ$497,24,0)/5 -> 0 | T150: =VLOOKUP($B150,'26년 1월 출석표'!$B$2:$BQ$497,38,0)/5 -> 0 | V150: =VLOOKUP($B150,'26년 1월 출석표'!$B$2:$BQ$497,52,0)/5 -> 0 | X150: =VLOOKUP($B150,'26년 1월 출석표'!$B$2:$BQ$503,66,0)/5 -> 0
B151: 배진선 | C151: 여 | D151: 010-5172-8628 | E151: FPT 12개월 | F151: 46020 | G151: 46027 | H151: 46391 | I151: =VLOOKUP(B151,'26년 1월 출석표'!$B$7:$D$500,3,0) -> 4 | J151: =ifna(I151/21,0) -> #NAME? | K151: =IF(AND(G151<=$L$4,H151>=$K$4),"유효","") -> 유효 | L151: =IF(AND(H151>=$K$4,H151<=$L$4),"만료","") | N151: FALSE | O151: FALSE | P151: =VLOOKUP($B151,'26년 1월 출석표'!$B$2:$BQ$497,10,0)/1 -> 0 | R151: =VLOOKUP($B151,'26년 1월 출석표'!$B$2:$BQ$497,24,0)/5 -> 0.6 | T151: =VLOOKUP($B151,'26년 1월 출석표'!$B$2:$BQ$497,38,0)/5 -> 0.2 | V151: =VLOOKUP($B151,'26년 1월 출석표'!$B$2:$BQ$497,52,0)/5 -> 0 | X151: =VLOOKUP($B151,'26년 1월 출석표'!$B$2:$BQ$503,66,0)/5 -> 0
B152: 문아인 | C152: 여 | D152: 010-4615-6586 | E152: FPT 2개월 | F152: 46021 | G152: 46023 | H152: 46082 | I152: =VLOOKUP(B152,'26년 1월 출석표'!$B$7:$D$500,3,0) -> 7 | J152: =ifna(I152/21,0) -> #NAME? | K152: =IF(AND(G152<=$L$4,H152>=$K$4),"유효","") -> 유효 | L152: =IF(AND(H152>=$K$4,H152<=$L$4),"만료","") | N152: FALSE | O152: FALSE | P152: =VLOOKUP($B152,'26년 1월 출석표'!$B$2:$BQ$497,10,0)/1 -> 1 | R152: =VLOOKUP($B152,'26년 1월 출석표'!$B$2:$BQ$497,24,0)/5 -> 1 | T152: =VLOOKUP($B152,'26년 1월 출석표'!$B$2:$BQ$497,38,0)/5 -> 0.2 | V152: =VLOOKUP($B152,'26년 1월 출석표'!$B$2:$BQ$497,52,0)/5 -> 0 | X152: =VLOOKUP($B152,'26년 1월 출석표'!$B$2:$BQ$503,66,0)/5 -> 0
B153: 김은혜B | C153: 여 | D153: 010-8102-7406 | E153: FPT 9개월 | F153: 46021 | G153: 46022 | H153: 46325 | I153: =VLOOKUP(B153,'26년 1월 출석표'!$B$7:$D$500,3,0) -> 4 | J153: =ifna(I153/21,0) -> #NAME? | K153: =IF(AND(G153<=$L$4,H153>=$K$4),"유효","") -> 유효 | L153: =IF(AND(H153>=$K$4,H153<=$L$4),"만료","") | N153: FALSE | O153: FALSE | P153: =VLOOKUP($B153,'26년 1월 출석표'!$B$2:$BQ$497,10,0)/1 -> 0 | R153: =VLOOKUP($B153,'26년 1월 출석표'!$B$2:$BQ$497,24,0)/5 -> 0.6 | T153: =VLOOKUP($B153,'26년 1월 출석표'!$B$2:$BQ$497,38,0)/5 -> 0.2 | V153: =VLOOKUP($B153,'26년 1월 출석표'!$B$2:$BQ$497,52,0)/5 -> 0 | X153: =VLOOKUP($B153,'26년 1월 출석표'!$B$2:$BQ$503,66,0)/5 -> 0
B154: 인소영 | C154: 여 | D154: 010-4015-0992 | E154: FPT 12개월 | F154: 46021 | G154: 46023 | H154: 46387 | I154: =VLOOKUP(B154,'26년 1월 출석표'!$B$7:$D$500,3,0) -> 6 | J154: =ifna(I154/21,0) -> #NAME? | K154: =IF(AND(G154<=$L$4,H154>=$K$4),"유효","") -> 유효 | L154: =IF(AND(H154>=$K$4,H154<=$L$4),"만료","") | N154: FALSE | O154: FALSE | P154: =VLOOKUP($B154,'26년 1월 출석표'!$B$2:$BQ$497,10,0)/1 -> 1 | R154: =VLOOKUP($B154,'26년 1월 출석표'!$B$2:$BQ$497,24,0)/5 -> 0.8 | T154: =VLOOKUP($B154,'26년 1월 출석표'!$B$2:$BQ$497,38,0)/5 -> 0.2 | V154: =VLOOKUP($B154,'26년 1월 출석표'!$B$2:$BQ$497,52,0)/5 -> 0 | X154: =VLOOKUP($B154,'26년 1월 출석표'!$B$2:$BQ$503,66,0)/5 -> 0
B155: 김진서 | C155: 여 | D155: 010-7673-4824 | E155: FPT 2개월 | F155: 46022 | G155: 46023 | H155: 46081 | I155: =VLOOKUP(B155,'26년 1월 출석표'!$B$7:$D$500,3,0) -> 1 | J155: =ifna(I155/21,0) -> #NAME? | K155: =IF(AND(G155<=$L$4,H155>=$K$4),"유효","") -> 유효 | L155: =IF(AND(H155>=$K$4,H155<=$L$4),"만료","") | N155: FALSE | O155: FALSE | P155: =VLOOKUP($B155,'26년 1월 출석표'!$B$2:$BQ$497,10,0)/1 -> 0 | R155: =VLOOKUP($B155,'26년 1월 출석표'!$B$2:$BQ$497,24,0)/5 -> 0 | T155: =VLOOKUP($B155,'26년 1월 출석표'!$B$2:$BQ$497,38,0)/5 -> 0.2 | V155: =VLOOKUP($B155,'26년 1월 출석표'!$B$2:$BQ$497,52,0)/5 -> 0 | X155: =VLOOKUP($B155,'26년 1월 출석표'!$B$2:$BQ$503,66,0)/5 -> 0
B156: 원정선 | C156: 여 | D156: 010-3880-9701 | E156: FPT 12개월 | F156: 46022 | G156: 46028 | H156: 46423 | I156: =VLOOKUP(B156,'26년 1월 출석표'!$B$7:$D$500,3,0) -> 1 | J156: =ifna(I156/21,0) -> #NAME? | K156: =IF(AND(G156<=$L$4,H156>=$K$4),"유효","") -> 유효 | L156: =IF(AND(H156>=$K$4,H156<=$L$4),"만료","") | N156: FALSE | O156: FALSE | P156: =VLOOKUP($B156,'26년 1월 출석표'!$B$2:$BQ$497,10,0)/1 -> 0 | R156: =VLOOKUP($B156,'26년 1월 출석표'!$B$2:$BQ$497,24,0)/5 -> 0.2 | T156: =VLOOKUP($B156,'26년 1월 출석표'!$B$2:$BQ$497,38,0)/5 -> 0 | V156: =VLOOKUP($B156,'26년 1월 출석표'!$B$2:$BQ$497,52,0)/5 -> 0 | X156: =VLOOKUP($B156,'26년 1월 출석표'!$B$2:$BQ$503,66,0)/5 -> 0
B157: 이민우 | C157: 남 | D157: 010-7339-6724 | E157: FPT 12개월 | F157: 46024 | G157: 46034 | H157: 46398 | I157: =VLOOKUP(B157,'26년 1월 출석표'!$B$7:$D$500,3,0) -> 1 | J157: =ifna(I157/21,0) -> #NAME? | K157: =IF(AND(G157<=$L$4,H157>=$K$4),"유효","") -> 유효 | L157: =IF(AND(H157>=$K$4,H157<=$L$4),"만료","") | N157: FALSE | O157: FALSE | P157: =VLOOKUP($B157,'26년 1월 출석표'!$B$2:$BQ$497,10,0)/1 -> 0 | R157: =VLOOKUP($B157,'26년 1월 출석표'!$B$2:$BQ$497,24,0)/5 -> 0 | T157: =VLOOKUP($B157,'26년 1월 출석표'!$B$2:$BQ$497,38,0)/5 -> 0.2 | V157: =VLOOKUP($B157,'26년 1월 출석표'!$B$2:$BQ$497,52,0)/5 -> 0 | X157: =VLOOKUP($B157,'26년 1월 출석표'!$B$2:$BQ$503,66,0)/5 -> 0
B158: 김민희 | C158: 여 | D158: 010-3553-7685 | E158: FPT 횟수권 | F158: 46025 | G158: 46027 | H158: - | I158: =VLOOKUP(B158,'26년 1월 출석표'!$B$7:$D$500,3,0) -> 1 | J158: =ifna(I158/21,0) -> #NAME? | K158: =IF(AND(G158<=$L$4,H158>=$K$4),"유효","") -> 유효 | L158: =IF(AND(H158>=$K$4,H158<=$L$4),"만료","") | N158: FALSE | O158: FALSE | P158: =VLOOKUP($B158,'26년 1월 출석표'!$B$2:$BQ$497,10,0)/1 -> 0 | R158: =VLOOKUP($B158,'26년 1월 출석표'!$B$2:$BQ$497,24,0)/5 -> 0.2 | T158: =VLOOKUP($B158,'26년 1월 출석표'!$B$2:$BQ$497,38,0)/5 -> 0 | V158: =VLOOKUP($B158,'26년 1월 출석표'!$B$2:$BQ$497,52,0)/5 -> 0 | X158: =VLOOKUP($B158,'26년 1월 출석표'!$B$2:$BQ$503,66,0)/5 -> 0
B159: 김은희 | C159: 여 | D159: 010-2477-5347 | E159: FPT 3개월 | F159: 46028 | G159: 46029 | H159: 46118 | I159: =VLOOKUP(B159,'26년 1월 출석표'!$B$7:$D$500,3,0) -> 4 | J159: =ifna(I159/21,0) -> #NAME? | K159: =IF(AND(G159<=$L$4,H159>=$K$4),"유효","") -> 유효 | L159: =IF(AND(H159>=$K$4,H159<=$L$4),"만료","") | N159: FALSE | O159: FALSE | P159: =VLOOKUP($B159,'26년 1월 출석표'!$B$2:$BQ$497,10,0)/1 -> 0 | R159: =VLOOKUP($B159,'26년 1월 출석표'!$B$2:$BQ$497,24,0)/5 -> 0.6 | T159: =VLOOKUP($B159,'26년 1월 출석표'!$B$2:$BQ$497,38,0)/5 -> 0.2 | V159: =VLOOKUP($B159,'26년 1월 출석표'!$B$2:$BQ$497,52,0)/5 -> 0 | X159: =VLOOKUP($B159,'26년 1월 출석표'!$B$2:$BQ$503,66,0)/5 -> 0
B160: 장규순 | C160: 여 | D160: 010-4001-4691 | E160: FPT 12개월 | F160: 46029 | G160: 46029 | H160: 46393 | I160: =VLOOKUP(B160,'26년 1월 출석표'!$B$7:$D$500,3,0) -> 4 | J160: =ifna(I160/21,0) -> #NAME? | K160: =IF(AND(G160<=$L$4,H160>=$K$4),"유효","") -> 유효 | L160: =IF(AND(H160>=$K$4,H160<=$L$4),"만료","") | N160: FALSE | O160: FALSE | P160: =VLOOKUP($B160,'26년 1월 출석표'!$B$2:$BQ$497,10,0)/1 -> 0 | R160: =VLOOKUP($B160,'26년 1월 출석표'!$B$2:$BQ$497,24,0)/5 -> 0.6 | T160: =VLOOKUP($B160,'26년 1월 출석표'!$B$2:$BQ$497,38,0)/5 -> 0.2 | V160: =VLOOKUP($B160,'26년 1월 출석표'!$B$2:$BQ$497,52,0)/5 -> 0 | X160: =VLOOKUP($B160,'26년 1월 출석표'!$B$2:$BQ$503,66,0)/5 -> 0
B161: 김영춘 | C161: 여 | D161: 010-2707-2110 | E161: FPT 12개월 | F161: 46031 | G161: 46034 | H161: 46398 | I161: =VLOOKUP(B161,'26년 1월 출석표'!$B$7:$D$500,3,0) -> 0 | J161: =ifna(I161/21,0) -> #NAME? | K161: =IF(AND(G161<=$L$4,H161>=$K$4),"유효","") -> 유효 | L161: =IF(AND(H161>=$K$4,H161<=$L$4),"만료","") | N161: FALSE | O161: FALSE | P161: =VLOOKUP($B161,'26년 1월 출석표'!$B$2:$BQ$497,10,0)/1 -> 0 | R161: =VLOOKUP($B161,'26년 1월 출석표'!$B$2:$BQ$497,24,0)/5 -> 0 | T161: =VLOOKUP($B161,'26년 1월 출석표'!$B$2:$BQ$497,38,0)/5 -> 0 | V161: =VLOOKUP($B161,'26년 1월 출석표'!$B$2:$BQ$497,52,0)/5 -> 0 | X161: =VLOOKUP($B161,'26년 1월 출석표'!$B$2:$BQ$503,66,0)/5 -> 0
B162: 안도담 | C162: 여 | D162: 010-4715-4511 | E162: FPT 2개월 | F162: 46032 | G162: 46034 | H162: 46092 | I162: =VLOOKUP(B162,'26년 1월 출석표'!$B$7:$D$500,3,0) -> 1 | J162: =ifna(I162/21,0) -> #NAME? | K162: =IF(AND(G162<=$L$4,H162>=$K$4),"유효","") -> 유효 | L162: =IF(AND(H162>=$K$4,H162<=$L$4),"만료","") | N162: TRUE | O162: FALSE | P162: =VLOOKUP($B162,'26년 1월 출석표'!$B$2:$BQ$497,10,0)/1 -> 0 | R162: =VLOOKUP($B162,'26년 1월 출석표'!$B$2:$BQ$497,24,0)/5 -> 0 | T162: =VLOOKUP($B162,'26년 1월 출석표'!$B$2:$BQ$497,38,0)/5 -> 0.2 | V162: =VLOOKUP($B162,'26년 1월 출석표'!$B$2:$BQ$497,52,0)/5 -> 0 | X162: =VLOOKUP($B162,'26년 1월 출석표'!$B$2:$BQ$503,66,0)/5 -> 0
B163: 안중원 | C163: 남 | D163: 010-5007-2357 | E163: FPT 2개월 | F163: 46032 | G163: 46034 | H163: 46092 | I163: =VLOOKUP(B163,'26년 1월 출석표'!$B$7:$D$500,3,0) -> 1 | J163: =ifna(I163/21,0) -> #NAME? | K163: =IF(AND(G163<=$L$4,H163>=$K$4),"유효","") -> 유효 | L163: =IF(AND(H163>=$K$4,H163<=$L$4),"만료","") | N163: TRUE | O163: FALSE | P163: =VLOOKUP($B163,'26년 1월 출석표'!$B$2:$BQ$497,10,0)/1 -> 0 | R163: =VLOOKUP($B163,'26년 1월 출석표'!$B$2:$BQ$497,24,0)/5 -> 0 | T163: =VLOOKUP($B163,'26년 1월 출석표'!$B$2:$BQ$497,38,0)/5 -> 0.2 | V163: =VLOOKUP($B163,'26년 1월 출석표'!$B$2:$BQ$497,52,0)/5 -> 0 | X163: =VLOOKUP($B163,'26년 1월 출석표'!$B$2:$BQ$503,66,0)/5 -> 0
B164: 차민경 | C164: 여 | D164: 010-6438-3708 | E164: FPT 6개월 | F164: 46034 | G164: 46035 | H164: 46215 | I164: =VLOOKUP(B164,'26년 1월 출석표'!$B$7:$D$500,3,0) -> 0 | J164: =ifna(I164/21,0) -> #NAME? | K164: =IF(AND(G164<=$L$4,H164>=$K$4),"유효","") -> 유효 | L164: =IF(AND(H164>=$K$4,H164<=$L$4),"만료","") | N164: FALSE | O164: FALSE | P164: =VLOOKUP($B164,'26년 1월 출석표'!$B$2:$BQ$497,10,0)/1 -> 0 | R164: =VLOOKUP($B164,'26년 1월 출석표'!$B$2:$BQ$497,24,0)/5 -> 0 | T164: =VLOOKUP($B164,'26년 1월 출석표'!$B$2:$BQ$497,38,0)/5 -> 0 | V164: =VLOOKUP($B164,'26년 1월 출석표'!$B$2:$BQ$497,52,0)/5 -> 0 | X164: =VLOOKUP($B164,'26년 1월 출석표'!$B$2:$BQ$503,66,0)/5 -> 0
I165: =VLOOKUP(B165,'26년 1월 출석표'!$B$7:$D$500,3,0) -> #N/A | J165: =ifna(I165/21,0) -> #NAME? | K165: =IF(AND(G165<=$L$4,H165>=$K$4),"유효","") | L165: =IF(AND(H165>=$K$4,H165<=$L$4),"만료","") | N165: FALSE | O165: FALSE | P165: =VLOOKUP($B165,'26년 1월 출석표'!$B$2:$BQ$497,10,0)/1 -> #N/A | R165: =VLOOKUP($B165,'26년 1월 출석표'!$B$2:$BQ$497,24,0)/5 -> #N/A | T165: =VLOOKUP($B165,'26년 1월 출석표'!$B$2:$BQ$497,38,0)/5 -> #N/A | V165: =VLOOKUP($B165,'26년 1월 출석표'!$B$2:$BQ$497,52,0)/5 -> #N/A | X165: =VLOOKUP($B165,'26년 1월 출석표'!$B$2:$BQ$503,66,0)/5 -> #N/A
I166: =VLOOKUP(B166,'26년 1월 출석표'!$B$7:$D$500,3,0) -> #N/A | J166: =ifna(I166/21,0) -> #NAME? | K166: =IF(AND(G166<=$L$4,H166>=$K$4),"유효","") | L166: =IF(AND(H166>=$K$4,H166<=$L$4),"만료","") | N166: FALSE | O166: FALSE | P166: =VLOOKUP($B166,'26년 1월 출석표'!$B$2:$BQ$497,10,0)/1 -> #N/A | R166: =VLOOKUP($B166,'26년 1월 출석표'!$B$2:$BQ$497,24,0)/5 -> #N/A | T166: =VLOOKUP($B166,'26년 1월 출석표'!$B$2:$BQ$497,38,0)/5 -> #N/A | V166: =VLOOKUP($B166,'26년 1월 출석표'!$B$2:$BQ$497,52,0)/5 -> #N/A | X166: =VLOOKUP($B166,'26년 1월 출석표'!$B$2:$BQ$503,66,0)/5 -> #N/A
I167: =VLOOKUP(B167,'26년 1월 출석표'!$B$7:$D$500,3,0) -> #N/A | J167: =ifna(I167/21,0) -> #NAME? | K167: =IF(AND(G167<=$L$4,H167>=$K$4),"유효","") | L167: =IF(AND(H167>=$K$4,H167<=$L$4),"만료","") | N167: FALSE | O167: FALSE | P167: =VLOOKUP($B167,'26년 1월 출석표'!$B$2:$BQ$497,10,0)/1 -> #N/A | R167: =VLOOKUP($B167,'26년 1월 출석표'!$B$2:$BQ$497,24,0)/5 -> #N/A | T167: =VLOOKUP($B167,'26년 1월 출석표'!$B$2:$BQ$497,38,0)/5 -> #N/A | V167: =VLOOKUP($B167,'26년 1월 출석표'!$B$2:$BQ$497,52,0)/5 -> #N/A | X167: =VLOOKUP($B167,'26년 1월 출석표'!$B$2:$BQ$503,66,0)/5 -> #N/A
I168: =VLOOKUP(B168,'26년 1월 출석표'!$B$7:$D$500,3,0) -> #N/A | J168: =ifna(I168/21,0) -> #NAME? | K168: =IF(AND(G168<=$L$4,H168>=$K$4),"유효","") | L168: =IF(AND(H168>=$K$4,H168<=$L$4),"만료","") | N168: FALSE | O168: FALSE | P168: =VLOOKUP($B168,'26년 1월 출석표'!$B$2:$BQ$497,10,0)/1 -> #N/A | R168: =VLOOKUP($B168,'26년 1월 출석표'!$B$2:$BQ$497,24,0)/5 -> #N/A | T168: =VLOOKUP($B168,'26년 1월 출석표'!$B$2:$BQ$497,38,0)/5 -> #N/A | V168: =VLOOKUP($B168,'26년 1월 출석표'!$B$2:$BQ$497,52,0)/5 -> #N/A | X168: =VLOOKUP($B168,'26년 1월 출석표'!$B$2:$BQ$503,66,0)/5 -> #N/A
I169: =VLOOKUP(B169,'26년 1월 출석표'!$B$7:$D$500,3,0) -> #N/A | J169: =ifna(I169/21,0) -> #NAME? | K169: =IF(AND(G169<=$L$4,H169>=$K$4),"유효","") | L169: =IF(AND(H169>=$K$4,H169<=$L$4),"만료","") | N169: FALSE | O169: FALSE | P169: =VLOOKUP($B169,'26년 1월 출석표'!$B$2:$BQ$497,10,0)/1 -> #N/A | R169: =VLOOKUP($B169,'26년 1월 출석표'!$B$2:$BQ$497,24,0)/5 -> #N/A | T169: =VLOOKUP($B169,'26년 1월 출석표'!$B$2:$BQ$497,38,0)/5 -> #N/A | V169: =VLOOKUP($B169,'26년 1월 출석표'!$B$2:$BQ$497,52,0)/5 -> #N/A | X169: =VLOOKUP($B169,'26년 1월 출석표'!$B$2:$BQ$503,66,0)/5 -> #N/A
I170: =VLOOKUP(B170,'26년 1월 출석표'!$B$7:$D$500,3,0) -> #N/A | J170: =ifna(I170/21,0) -> #NAME? | K170: =IF(AND(G170<=$L$4,H170>=$K$4),"유효","") | L170: =IF(AND(H170>=$K$4,H170<=$L$4),"만료","") | N170: FALSE | O170: FALSE | P170: =VLOOKUP($B170,'26년 1월 출석표'!$B$2:$BQ$497,10,0)/1 -> #N/A | R170: =VLOOKUP($B170,'26년 1월 출석표'!$B$2:$BQ$497,24,0)/5 -> #N/A | T170: =VLOOKUP($B170,'26년 1월 출석표'!$B$2:$BQ$497,38,0)/5 -> #N/A | V170: =VLOOKUP($B170,'26년 1월 출석표'!$B$2:$BQ$497,52,0)/5 -> #N/A | X170: =VLOOKUP($B170,'26년 1월 출석표'!$B$2:$BQ$503,66,0)/5 -> #N/A
I171: =VLOOKUP(B171,'26년 1월 출석표'!$B$7:$D$500,3,0) -> #N/A | J171: =ifna(I171/21,0) -> #NAME? | K171: =IF(AND(G171<=$L$4,H171>=$K$4),"유효","") | L171: =IF(AND(H171>=$K$4,H171<=$L$4),"만료","") | N171: FALSE | O171: FALSE | P171: =VLOOKUP($B171,'26년 1월 출석표'!$B$2:$BQ$497,10,0)/1 -> #N/A | R171: =VLOOKUP($B171,'26년 1월 출석표'!$B$2:$BQ$497,24,0)/5 -> #N/A | T171: =VLOOKUP($B171,'26년 1월 출석표'!$B$2:$BQ$497,38,0)/5 -> #N/A | V171: =VLOOKUP($B171,'26년 1월 출석표'!$B$2:$BQ$497,52,0)/5 -> #N/A | X171: =VLOOKUP($B171,'26년 1월 출석표'!$B$2:$BQ$503,66,0)/5 -> #N/A
...

Sheet 26년 1월 출석표
A1: ㄹ | B1: 1 | C1: 2 | D1: 3 | E1: 4 | F1: 5 | G1: 6 | H1: 7 | I1: 8 | J1: 9 | K1: 10 | L1: 11 | M1: 12 | N1: 13 | O1: 14 | P1: 15 | Q1: 16 | R1: 17 | S1: 18 | T1: 19 | U1: 20 | V1: 21 | W1: 22 | X1: 23 | Y1: 24 | Z1: 25 | AA1: 26 | AB1: 27 | AC1: 28 | AD1: 29 | AE1: 30 | AF1: 31 | AG1: 32 | AH1: 33 | AI1: 34 | AJ1: 35 | AK1: 36 | AL1: 37 | AM1: 38 | AN1: 39 | AO1: 40 | AP1: 41 | AQ1: 42 | AR1: 43 | AS1: 44 | AT1: 45 | AU1: 46 | AV1: 47 | AW1: 48 | AX1: 49 | AY1: 50 | AZ1: 51 | BA1: 52 | BB1: 53 | BC1: 54 | BD1: 55 | BE1: 56 | BF1: 57 | BG1: 58 | BH1: 59 | BI1: 60 | BJ1: 61 | BK1: 62 | BL1: 63 | BM1: 64 | BN1: 65 | BO1: 66 | BP1: 67 | BQ1: 68 | BU1: 누적 | BV1: =SUM(BV3:BV7) -> 364 | BW1: =SUM(BW3:BW7) -> 21 | BX1: =BV1/BW1 -> 17.333333 | BY1: =BX1/BY2 -> 0.10901468
B2: 26.1월 | E2: 1 | G2: 2 | I2: 3 | K2: 4 | M2: 5 | O2: 6 | Q2: 7 | S2: 8 | U2: 9 | W2: 10 | Y2: 11 | AA2: 12 | AC2: 13 | AE2: 14 | AG2: 15 | AI2: 16 | AK2: 17 | AM2: 18 | AO2: 19 | AQ2: 20 | AS2: 21 | AU2: 22 | AW2: 23 | AY2: 24 | BA2: 25 | BC2: 26 | BE2: 27 | BG2: 28 | BI2: 29 | BK2: 30 | BM2: 31 | BR2: 평균 | BU2: 주차 | BV2: 출석수 | BW2: 일수 | BX2: 평균 | BY2: ='26년 1월 유효회원'!C3 -> 159 | CA2: 홍은
D3: 수 | E3: =COUNTA(E7:E500) -> 14 | G3: =COUNTA(G7:G500) -> 42 | I3: =COUNTA(I7:I500) -> 13 | K3: =SUM(K7:K500) -> 42 | M3: =COUNTA(M7:M500) -> 65 | O3: =COUNTA(O7:O500) -> 52 | Q3: =COUNTA(Q7:Q500) -> 48 | S3: =COUNTA(S7:S500) -> 52 | U3: =COUNTA(U7:U500) -> 47 | W3: =COUNTA(W7:W500) -> 8 | Y3: =SUM(Y7:Y500) -> 264 | AA3: =COUNTA(AA7:AA500) -> 58 | AC3: =COUNTA(AC7:AC500) -> 0 | AE3: =COUNTA(AE7:AE500) -> 0 | AG3: =COUNTA(AG7:AG500) -> 0 | AI3: =COUNTA(AI7:AI500) -> 0 | AK3: =COUNTA(AK7:AK500) -> 0 | AM3: =SUM(AM7:AM500) -> 58 | AO3: =COUNTA(AO7:AO500) -> 0 | AQ3: =COUNTA(AQ7:AQ500) -> 0 | AS3: =COUNTA(AS7:AS500) -> 0 | AU3: =COUNTA(AU7:AU500) -> 0 | AW3: =COUNTA(AW7:AW500) -> 0 | AY3: =COUNTA(AY7:AY500) -> 0 | BA3: =SUM(BA7:BA500) -> 0 | BC3: =COUNTA(BC7:BC500) -> 0 | BE3: =COUNTA(BE7:BE500) -> 0 | BG3: =COUNTA(BG7:BG500) -> 0 | BI3: =COUNTA(BI7:BI500) -> 0 | BK3: =COUNTA(BK7:BK500) -> 0 | BM3: =COUNTA(BM7:BM500) -> 0 | BO3: =SUM(BO7:BO500) -> 0 | BR3: =AVERAGE(K3,Y3,AM3,BO3) -> 91 | BU3: 1 | BV3: =K3 -> 42 | BW3: 1 | BX3: =BV3/BW3 -> 42 | BY3: =BX3/BY2 -> 0.26415094
D4: 율 | E4: =E3/'25년 12월 유효회원'!$C$3 -> 0.092715232 | G4: =G3/'25년 12월 유효회원'!$C$3 -> 0.2781457 | I4: =I3/'25년 12월 유효회원'!$C$3 -> 0.086092715 | K4: =K3/'26년 1월 유효회원'!$C$3 -> 0.26415094 | M4: =M3/'25년 12월 유효회원'!$C$3 -> 0.43046358 | O4: =O3/'25년 12월 유효회원'!$C$3 -> 0.34437086 | Q4: =Q3/'25년 12월 유효회원'!$C$3 -> 0.31788079 | S4: =S3/'25년 12월 유효회원'!$C$3 -> 0.34437086 | U4: =U3/'25년 12월 유효회원'!$C$3 -> 0.31125828 | W4: =W3/'25년 12월 유효회원'!$C$3 -> 0.052980132 | Y4: =Y3/'26년 1월 유효회원'!$C$3 -> 1.6603774 | AA4: =AA3/'25년 12월 유효회원'!$C$3 -> 0.38410596 | AC4: =AC3/'25년 12월 유효회원'!$C$3 -> 0 | AE4: =AE3/'25년 12월 유효회원'!$C$3 -> 0 | AG4: =AG3/'25년 12월 유효회원'!$C$3 -> 0 | AI4: =AI3/'25년 12월 유효회원'!$C$3 -> 0 | AK4: =AK3/'25년 12월 유효회원'!$C$3 -> 0 | AM4: =AM3/'26년 1월 유효회원'!$C$3 -> 0.36477987 | AO4: =AO3/'25년 12월 유효회원'!$C$3 -> 0 | AQ4: =AQ3/'25년 12월 유효회원'!$C$3 -> 0 | AS4: =AS3/'25년 12월 유효회원'!$C$3 -> 0 | AU4: =AU3/'25년 12월 유효회원'!$C$3 -> 0 | AW4: =AW3/'25년 12월 유효회원'!$C$3 -> 0 | AY4: =AY3/'25년 12월 유효회원'!$C$3 -> 0 | BA4: =BA3/'26년 1월 유효회원'!$C$3 -> 0 | BC4: =BC3/'25년 12월 유효회원'!$C$3 -> 0 | BE4: =BE3/'25년 12월 유효회원'!$C$3 -> 0 | BG4: =BG3/'25년 12월 유효회원'!$C$3 -> 0 | BI4: =BI3/'25년 12월 유효회원'!$C$3 -> 0 | BK4: =BK3/'25년 12월 유효회원'!$C$3 -> 0 | BM4: =BM3/'25년 12월 유효회원'!$C$3 -> 0 | BO4: =BO3/'26년 1월 유효회원'!$C$3 -> 0 | BU4: 2 | BV4: =Y3 -> 264 | BW4: 5 | BX4: =BV4/BW4 -> 52.8 | BY4: =BX4/$BY$2 -> 0.33207547
A5: s . 신규 | E5: 남 | F5: 여 | G5: 남 | H5: 여 | I5: 남 | J5: 여 | K5: 남 | L5: 여 | M5: 남 | N5: 여 | O5: 남 | P5: 여 | Q5: 남 | R5: 여 | S5: 남 | T5: 여 | U5: 남 | V5: 여 | W5: 남 | X5: 여 | Y5: 남 | Z5: 여 | AA5: 남 | AB5: 여 | AC5: 남 | AD5: 여 | AE5: 남 | AF5: 여 | AG5: 남 | AH5: 여 | AI5: 남 | AJ5: 여 | AK5: 남 | AL5: 여 | AM5: 남 | AN5: 여 | AO5: 남 | AP5: 여 | AQ5: 남 | AR5: 여 | AS5: 남 | AT5: 여 | AU5: 남 | AV5: 여 | AW5: 남 | AX5: 여 | AY5: 남 | AZ5: 여 | BA5: 남 | BB5: 여 | BC5: 남 | BD5: 여 | BE5: 남 | BF5: 여 | BG5: 남 | BH5: 여 | BI5: 남 | BJ5: 여 | BK5: 남 | BL5: 여 | BM5: 남 | BN5: 여 | BO5: 남 | BP5: 여 | BU5: 3 | BV5: =AM3 -> 58 | BW5: 5 | BX5: =BV5/BW5 -> 11.6 | BY5: =BX5/$BY$2 -> 0.072955975
A6: r 기존. | B6: 이름 | C6: 성별 | D6: 수 | E6: =COUNTIFS($C$7:$C$432,"남",E7:E432,"<>") -> 4 | F6: =COUNTIFS($C$7:$C$432,"여",E7:E432,"<>") -> 10 | G6: =COUNTIFS($C$7:$C$432,"남",G7:G432,"<>") -> 7 | H6: =COUNTIFS($C$7:$C$432,"여",G7:G432,"<>") -> 35 | I6: =COUNTIFS($C$7:$C$432,"남",I7:I432,"<>") -> 2 | J6: =COUNTIFS($C$7:$C$432,"여",I7:I432,"<>") -> 11 | K6: =SUM(G6) -> 7 | L6: =SUM(H6) -> 35 | M6: =COUNTIFS($C$7:$C$432,"남",M7:M432,"<>") -> 14 | N6: =COUNTIFS($C$7:$C$432,"남",N7:N432,"<>") -> 0 | O6: =COUNTIFS($C$7:$C$432,"남",O7:O432,"<>") -> 10 | P6: =COUNTIFS($C$7:$C$432,"남",P7:P432,"<>") -> 0 | Q6: =COUNTIFS($C$7:$C$432,"남",Q7:Q432,"<>") -> 9 | R6: =COUNTIFS($C$7:$C$432,"남",R7:R432,"<>") -> 0 | S6: =COUNTIFS($C$7:$C$432,"남",S7:S432,"<>") -> 9 | T6: =COUNTIFS($C$7:$C$432,"여",S7:S432,"<>") -> 43 | U6: =COUNTIFS($C$7:$C$432,"남",U7:U432,"<>") -> 10 | V6: =COUNTIFS($C$7:$C$432,"여",U7:U432,"<>") -> 37 | W6: =COUNTIFS($C$7:$C$432,"남",W7:W432,"<>") -> 1 | X6: =COUNTIFS($C$7:$C$432,"여",W7:W432,"<>") -> 7 | Y6: =SUM(M6,O6,Q6,S6,U6) -> 52 | Z6: =SUM(N6,P6,R6,T6,V6) -> 80 | AA6: =COUNTIFS($C$7:$C$432,"남",AA7:AA432,"<>") -> 6 | AB6: =COUNTIFS($C$7:$C$432,"여",AA7:AA432,"<>") -> 52 | AC6: =COUNTIFS($C$7:$C$432,"여",AB7:AB432,"<>") -> 0 | AD6: =COUNTIFS($C$7:$C$432,"여",AC7:AC432,"<>") -> 0 | AE6: =COUNTIFS($C$7:$C$432,"여",AD7:AD432,"<>") -> 0 | AF6: =COUNTIFS($C$7:$C$432,"여",AE7:AE432,"<>") -> 0 | AG6: =COUNTIFS($C$7:$C$432,"남",AG7:AG432,"<>") -> 0 | AH6: =COUNTIFS($C$7:$C$432,"여",AG7:AG432,"<>") -> 0 | AI6: =COUNTIFS($C$7:$C$432,"남",AI7:AI432,"<>") -> 0 | AJ6: =COUNTIFS($C$7:$C$432,"여",AI7:AI432,"<>") -> 0 | AK6: =COUNTIFS($C$7:$C$432,"남",AK7:AK432,"<>") -> 0 | AL6: =COUNTIFS($C$7:$C$432,"여",AK7:AK432,"<>") -> 0 | AM6: =SUM(AA6,AC6,AE6,AG6,AI6) -> 6 | AN6: =SUM(AB6,AD6,AF6,AH6,AJ6) -> 52 | AO6: =COUNTIFS($C$7:$C$432,"남",AO7:AO432,"<>") -> 0 | AP6: =COUNTIFS($C$7:$C$432,"여",AO7:AO432,"<>") -> 0 | AQ6: =COUNTIFS($C$7:$C$432,"남",AQ7:AQ432,"<>") -> 0 | AR6: =COUNTIFS($C$7:$C$432,"여",AQ7:AQ432,"<>") -> 0 | AS6: =COUNTIFS($C$7:$C$432,"남",AS7:AS432,"<>") -> 0 | AT6: =COUNTIFS($C$7:$C$432,"여",AS7:AS432,"<>") -> 0 | AU6: =COUNTIFS($C$7:$C$432,"남",AU7:AU432,"<>") -> 0 | AV6: =COUNTIFS($C$7:$C$432,"여",AU7:AU432,"<>") -> 0 | AW6: =COUNTIFS($C$7:$C$432,"남",AW7:AW432,"<>") -> 0 | AX6: =COUNTIFS($C$7:$C$432,"여",AW7:AW432,"<>") -> 0 | AY6: =COUNTIFS($C$7:$C$432,"남",AY7:AY432,"<>") -> 0 | AZ6: =COUNTIFS($C$7:$C$432,"여",AY7:AY432,"<>") -> 0 | BA6: =SUM(AO6,AQ6,AS6,AU6,AW6) -> 0 | BB6: =SUM(AP6,AR6,AT6,AV6,AX6) -> 0 | BC6: =COUNTIFS($C$7:$C$432,"남",BC7:BC432,"<>") -> 0 | BD6: =COUNTIFS($C$7:$C$432,"여",BC7:BC432,"<>") -> 0 | BE6: =COUNTIFS($C$7:$C$432,"여",BD7:BD432,"<>") -> 0 | BF6: =COUNTIFS($C$7:$C$432,"여",BE7:BE432,"<>") -> 0 | BG6: =COUNTIFS($C$7:$C$432,"남",BG7:BG432,"<>") -> 0 | BH6: =COUNTIFS($C$7:$C$432,"여",BG7:BG432,"<>") -> 0 | BI6: =COUNTIFS($C$7:$C$432,"남",BI7:BI432,"<>") -> 0 | BJ6: =COUNTIFS($C$7:$C$432,"여",BI7:BI432,"<>") -> 0 | BK6: 0 | BL6: =COUNTIFS($C$7:$C$432,"여",BK7:BK432,"<>") -> 0 | BM6: =COUNTIFS($C$7:$C$432,"남",BM7:BM432,"<>") -> 0 | BN6: =COUNTIFS($C$7:$C$432,"여",BM7:BM432,"<>") -> 0 | BO6: =SUM(K6,Y6,AM6,BA6) -> 65 | BP6: =SUM(L6,Z6,AN6,BB6) -> 167 | BU6: 4 | BV6: =BA3 -> 0 | BW6: 5 | BX6: =BV6/BW6 -> 0 | BY6: =BX6/$BY$2 -> 0
A7: mr 살몬 | BU7: 5 | BV7: =BO3 -> 0 | BW7: 5 | BX7: =BV7/BW7 -> 0 | BY7: =BX7/$BY$2 -> 0
B8: 김정숙 | C8: 여 | D8: =SUM(K8,Y8,AM8,BA8,BO8) -> 2 | K8: =COUNTA(G8:H8) -> 0 | O8: 12 | S8: 12 | Y8: =COUNTA(M8:V8) -> 2 | AM8: =COUNTA(AA8:AJ8) -> 0 | BA8: =COUNTA(AO8:AX8) -> 0 | BO8: =COUNTA(BC8:BL8) -> 0
B9: 신하영 | C9: 여 | D9: =SUM(K9,Y9,AM9,BA9,BO9) -> 0 | K9: =COUNTA(G9:H9) -> 0 | Y9: =COUNTA(M9:V9) -> 0 | AM9: =COUNTA(AA9:AJ9) -> 0 | BA9: =COUNTA(AO9:AX9) -> 0 | BO9: =COUNTA(BC9:BL9) -> 0 | BV9: 시간대별 출석인원 및 비율
B10: 정지우 | C10: 여 | D10: =SUM(K10,Y10,AM10,BA10,BO10) -> 3 | K10: =COUNTA(G10:H10) -> 0 | M10: 21 | O10: 20 | S10: 21 | Y10: =COUNTA(M10:V10) -> 3 | AM10: =COUNTA(AA10:AJ10) -> 0 | BA10: =COUNTA(AO10:AX10) -> 0 | BO10: =COUNTA(BC10:BL10) -> 0
B11: 곽상희 | C11: 여 | D11: =SUM(K11,Y11,AM11,BA11,BO11) -> 0 | K11: =COUNTA(G11:H11) -> 0 | Y11: =COUNTA(M11:V11) -> 0 | AM11: =COUNTA(AA11:AJ11) -> 0 | BA11: =COUNTA(AO11:AX11) -> 0 | BO11: =COUNTA(BC11:BL11) -> 0 | BV11: 1주차 | CA11: 수업료 계산 평균 인원
B12: 임성빈 | C12: 남 | D12: =SUM(K12,Y12,AM12,BA12,BO12) -> 0 | K12: =COUNTA(G12:H12) -> 0 | Y12: =COUNTA(M12:V12) -> 0 | AM12: =COUNTA(AA12:AJ12) -> 0 | BA12: =COUNTA(AO12:AX12) -> 0 | BO12: =COUNTA(BC12:BL12) -> 0 | BV12: 시간 | BW12: 출석인원 | BX12: % | BY12: 평균 | CA12: 시간 | CC12: 평균
B13: 이난영 | C13: 여 | D13: =SUM(K13,Y13,AM13,BA13,BO13) -> 0 | K13: =COUNTA(G13:H13) -> 0 | Y13: =COUNTA(M13:V13) -> 0 | AM13: =COUNTA(AA13:AJ13) -> 0 | BA13: =COUNTA(AO13:AX13) -> 0 | BO13: =COUNTA(BC13:BL13) -> 0 | BV13: 7 | BW13: =IFERROR(__xludf.DUMMYFUNCTION("COUNTIF(MAP($G$8:$H$503,LAMBDA(c,IF(TRIM(c)="""","""",MIN(VALUE(SPLIT(SUBSTITUTE(SUBSTITUTE(SUBSTITUTE(c,"" "",""""),""，"","",""),"";"","",""),"","")))))),BV13)"),2) -> 2 | BX13: =BW13/SUM($BW$13:$BW$22)*100 -> 4.7619048 | BY13: =BW13/$BW$3 -> 2 | CA13: 7 | CC13: =ROUND(SUM(BW13,BW25,BW37,BW49,BW61)/$BW$1,0) -> 1
B14: 이지현 | C14: 여 | D14: =SUM(K14,Y14,AM14,BA14,BO14) -> 2 | K14: =COUNTA(G14:H14) -> 0 | O14: 21 | S14: 21 | Y14: =COUNTA(M14:V14) -> 2 | AM14: =COUNTA(AA14:AJ14) -> 0 | BA14: =COUNTA(AO14:AX14) -> 0 | BO14: =COUNTA(BC14:BL14) -> 0 | BV14: 8 | BW14: =IFERROR(__xludf.DUMMYFUNCTION("COUNTIF(MAP($G$8:$H$503,LAMBDA(c,IF(TRIM(c)="""","""",MIN(VALUE(SPLIT(SUBSTITUTE(SUBSTITUTE(SUBSTITUTE(c,"" "",""""),""，"","",""),"";"","",""),"","")))))),BV14)"),5) -> 5 | BX14: =BW14/SUM($BW$13:$BW$22)*100 -> 11.904762 | BY14: =BW14/$BW$3 -> 5 | CA14: 8 | CC14: =ROUND(SUM(BW14,BW26,BW38,BW50,BW62)/$BW$1,0) -> 1
B15: 정유찬 | C15: 남 | D15: =SUM(K15,Y15,AM15,BA15,BO15) -> 4 | K15: =COUNTA(G15:H15) -> 0 | M15: 19 | Q15: 12 | U15: 19 | Y15: =COUNTA(M15:V15) -> 3 | AA15: 18 | AM15: =COUNTA(AA15:AJ15) -> 1 | BA15: =COUNTA(AO15:AX15) -> 0 | BO15: =COUNTA(BC15:BL15) -> 0 | BV15: 10 | BW15: =IFERROR(__xludf.DUMMYFUNCTION("COUNTIF(MAP($G$8:$H$503,LAMBDA(c,IF(TRIM(c)="""","""",MIN(VALUE(SPLIT(SUBSTITUTE(SUBSTITUTE(SUBSTITUTE(c,"" "",""""),""，"","",""),"";"","",""),"","")))))),BV15)"),6) -> 6 | BX15: =BW15/SUM($BW$13:$BW$22)*100 -> 14.285714 | BY15: =BW15/$BW$3 -> 6 | CA15: 10 | CC15: =ROUND(SUM(BW15,BW27,BW39,BW51,BW63)/$BW$1,0) -> 2
B16: 전용순 | C16: 여 | D16: =SUM(K16,Y16,AM16,BA16,BO16) -> 6 | G16: 17 | K16: =COUNTA(G16:H16) -> 1 | O16: 17 | Q16: 17 | S16: 17 | U16: 17 | Y16: =COUNTA(M16:V16) -> 4 | AA16: 17 | AM16: =COUNTA(AA16:AJ16) -> 1 | BA16: =COUNTA(AO16:AX16) -> 0 | BO16: =COUNTA(BC16:BL16) -> 0 | BV16: 12 | BW16: =IFERROR(__xludf.DUMMYFUNCTION("COUNTIF(MAP($G$8:$H$503,LAMBDA(c,IF(TRIM(c)="""","""",MIN(VALUE(SPLIT(SUBSTITUTE(SUBSTITUTE(SUBSTITUTE(c,"" "",""""),""，"","",""),"";"","",""),"","")))))),BV16)"),4) -> 4 | BX16: =BW16/SUM($BW$13:$BW$22)*100 -> 9.5238095 | BY16: =BW16/$BW$3 -> 4 | CA16: 12 | CC16: =ROUND(SUM(BW16,BW28,BW40,BW52,BW64)/$BW$1,0) -> 2
B17: 김용희 | C17: 남 | D17: =SUM(K17,Y17,AM17,BA17,BO17) -> 1 | K17: =COUNTA(G17:H17) -> 0 | U17: 18 | Y17: =COUNTA(M17:V17) -> 1 | AM17: =COUNTA(AA17:AJ17) -> 0 | BA17: =COUNTA(AO17:AX17) -> 0 | BO17: =COUNTA(BC17:BL17) -> 0 | BV17: 17 | BW17: =IFERROR(__xludf.DUMMYFUNCTION("COUNTIF(MAP($G$8:$H$503,LAMBDA(c,IF(TRIM(c)="""","""",MIN(VALUE(SPLIT(SUBSTITUTE(SUBSTITUTE(SUBSTITUTE(c,"" "",""""),""，"","",""),"";"","",""),"","")))))),BV17)"),9) -> 9 | BX17: =BW17/SUM($BW$13:$BW$22)*100 -> 21.428571 | BY17: =BW17/$BW$3 -> 9 | CA17: 17 | CC17: =ROUND(SUM(BW17,BW29,BW41,BW53,BW65)/$BW$1,0) -> 3
B18: 황서영 | C18: 여 | D18: =SUM(K18,Y18,AM18,BA18,BO18) -> 6 | G18: 17 | K18: =COUNTA(G18:H18) -> 1 | M18: 17 | Q18: 17 | S18: 17 | U18: 17 | Y18: =COUNTA(M18:V18) -> 4 | AA18: 17 | AM18: =COUNTA(AA18:AJ18) -> 1 | BA18: =COUNTA(AO18:AX18) -> 0 | BO18: =COUNTA(BC18:BL18) -> 0 | BV18: 18 | BW18: =IFERROR(__xludf.DUMMYFUNCTION("COUNTIF(MAP($G$8:$H$503,LAMBDA(c,IF(TRIM(c)="""","""",MIN(VALUE(SPLIT(SUBSTITUTE(SUBSTITUTE(SUBSTITUTE(c,"" "",""""),""，"","",""),"";"","",""),"","")))))),BV18)"),5) -> 5 | BX18: =BW18/SUM($BW$13:$BW$22)*100 -> 11.904762 | BY18: =BW18/$BW$3 -> 5 | CA18: 18 | CC18: =ROUND(SUM(BW18,BW30,BW42,BW54,BW66)/$BW$1,0) -> 2
B19: 박유나 | C19: 여 | D19: =SUM(K19,Y19,AM19,BA19,BO19) -> 1 | K19: =COUNTA(G19:H19) -> 0 | Y19: =COUNTA(M19:V19) -> 0 | AA19: 7 | AM19: =COUNTA(AA19:AJ19) -> 1 | BA19: =COUNTA(AO19:AX19) -> 0 | BO19: =COUNTA(BC19:BL19) -> 0 | BV19: 19 | BW19: =IFERROR(__xludf.DUMMYFUNCTION("COUNTIF(MAP($G$8:$H$503,LAMBDA(c,IF(TRIM(c)="""","""",MIN(VALUE(SPLIT(SUBSTITUTE(SUBSTITUTE(SUBSTITUTE(c,"" "",""""),""，"","",""),"";"","",""),"","")))))),BV19)"),1) -> 1 | BX19: =BW19/SUM($BW$13:$BW$22)*100 -> 2.3809524 | BY19: =BW19/$BW$3 -> 1 | CA19: 19 | CC19: =ROUND(SUM(BW19,BW31,BW43,BW55,BW67)/$BW$1,0) -> 1
B20: 김지윤 | C20: 여 | D20: =SUM(K20,Y20,AM20,BA20,BO20) -> 6 | G20: 18 | K20: =COUNTA(G20:H20) -> 1 | M20: 20 | O20: 20 | S20: 20 | U20: 19 | Y20: =COUNTA(M20:V20) -> 4 | AA20: 20 | AM20: =COUNTA(AA20:AJ20) -> 1 | BA20: =COUNTA(AO20:AX20) -> 0 | BO20: =COUNTA(BC20:BL20) -> 0 | BV20: 20 | BW20: =IFERROR(__xludf.DUMMYFUNCTION("COUNTIF(MAP($G$8:$H$503,LAMBDA(c,IF(TRIM(c)="""","""",MIN(VALUE(SPLIT(SUBSTITUTE(SUBSTITUTE(SUBSTITUTE(c,"" "",""""),""，"","",""),"";"","",""),"","")))))),BV20)"),5) -> 5 | BX20: =BW20/SUM($BW$13:$BW$22)*100 -> 11.904762 | BY20: =BW20/$BW$3 -> 5 | CA20: 20 | CC20: =ROUND(SUM(BW20,BW32,BW44,BW56,BW68)/$BW$1,0) -> 3
B21: 오현옥 | C21: 여 | D21: =SUM(K21,Y21,AM21,BA21,BO21) -> 0 | K21: =COUNTA(G21:H21) -> 0 | Y21: =COUNTA(M21:V21) -> 0 | AM21: =COUNTA(AA21:AJ21) -> 0 | BA21: =COUNTA(AO21:AX21) -> 0 | BO21: =COUNTA(BC21:BL21) -> 0 | BV21: 21 | BW21: =IFERROR(__xludf.DUMMYFUNCTION("COUNTIF(MAP($G$8:$H$503,LAMBDA(c,IF(TRIM(c)="""","""",MIN(VALUE(SPLIT(SUBSTITUTE(SUBSTITUTE(SUBSTITUTE(c,"" "",""""),""，"","",""),"";"","",""),"","")))))),BV21)"),5) -> 5 | BX21: =BW21/SUM($BW$13:$BW$22)*100 -> 11.904762 | BY21: =BW21/$BW$3 -> 5 | CA21: 21 | CC21: =ROUND(SUM(BW21,BW33,BW45,BW57,BW69)/$BW$1,0) -> 2
B22: 정현주 | C22: 여 | D22: =SUM(K22,Y22,AM22,BA22,BO22) -> 0 | K22: =COUNTA(G22:H22) -> 0 | Y22: =COUNTA(M22:V22) -> 0 | AM22: =COUNTA(AA22:AJ22) -> 0 | BA22: =COUNTA(AO22:AX22) -> 0 | BO22: =COUNTA(BC22:BL22) -> 0
B23: 박형선 | C23: 여 | D23: =SUM(K23,Y23,AM23,BA23,BO23) -> 0 | K23: =COUNTA(G23:H23) -> 0 | Y23: =COUNTA(M23:V23) -> 0 | AM23: =COUNTA(AA23:AJ23) -> 0 | BA23: =COUNTA(AO23:AX23) -> 0 | BO23: =COUNTA(BC23:BL23) -> 0 | BV23: 2주차
B24: 이자경 | C24: 여 | D24: =SUM(K24,Y24,AM24,BA24,BO24) -> 1 | K24: =COUNTA(G24:H24) -> 0 | Y24: =COUNTA(M24:V24) -> 0 | AA24: 8 | AM24: =COUNTA(AA24:AJ24) -> 1 | BA24: =COUNTA(AO24:AX24) -> 0 | BO24: =COUNTA(BC24:BL24) -> 0 | BV24: 시간 | BW24: 출석인원 | BX24: % | BY24: 평균
B25: 박현미 | C25: 여 | D25: =SUM(K25,Y25,AM25,BA25,BO25) -> 6 | K25: =COUNTA(G25:H25) -> 0 | M25: 17 | O25: 17 | Q25: 10 | S25: 17 | U25: 17 | Y25: =COUNTA(M25:V25) -> 5 | AA25: 17 | AM25: =COUNTA(AA25:AJ25) -> 1 | BA25: =COUNTA(AO25:AX25) -> 0 | BO25: =COUNTA(BC25:BL25) -> 0 | BV25: 7 | BW25: =IFERROR(__xludf.DUMMYFUNCTION("COUNTIF(MAP($M$8:$V$500,LAMBDA(c,IF(TRIM(c)="""","""",MIN(VALUE(SPLIT(SUBSTITUTE(SUBSTITUTE(SUBSTITUTE(c,"" "",""""),""，"","",""),"";"","",""),"","")))))),BV25)"),6) -> 6 | BX25: =BW25/SUM($BW$25:$BW$34)*100 -> 2.2813688 | BY25: =BW25/$BW$4 -> 1.2
B26: 김수현 | C26: 여 | D26: =SUM(K26,Y26,AM26,BA26,BO26) -> 0 | K26: =COUNTA(G26:H26) -> 0 | Y26: =COUNTA(M26:V26) -> 0 | AM26: =COUNTA(AA26:AJ26) -> 0 | BA26: =COUNTA(AO26:AX26) -> 0 | BO26: =COUNTA(BC26:BL26) -> 0 | BV26: 8 | BW26: =IFERROR(__xludf.DUMMYFUNCTION("COUNTIF(MAP($M$8:$V$500,LAMBDA(c,IF(TRIM(c)="""","""",MIN(VALUE(SPLIT(SUBSTITUTE(SUBSTITUTE(SUBSTITUTE(c,"" "",""""),""，"","",""),"";"","",""),"","")))))),BV26)"),20) -> 20 | BX26: =BW26/SUM($BW$25:$BW$34)*100 -> 7.6045627 | BY26: =BW26/$BW$4 -> 4
B27: 고경민 | C27: 여 | D27: =SUM(K27,Y27,AM27,BA27,BO27) -> 2 | K27: =COUNTA(G27:H27) -> 0 | M27: 17 | O27: 12 | Y27: =COUNTA(M27:V27) -> 2 | AM27: =COUNTA(AA27:AJ27) -> 0 | BA27: =COUNTA(AO27:AX27) -> 0 | BO27: =COUNTA(BC27:BL27) -> 0 | BV27: 10 | BW27: =IFERROR(__xludf.DUMMYFUNCTION("COUNTIF(MAP($M$8:$V$500,LAMBDA(c,IF(TRIM(c)="""","""",MIN(VALUE(SPLIT(SUBSTITUTE(SUBSTITUTE(SUBSTITUTE(c,"" "",""""),""，"","",""),"";"","",""),"","")))))),BV27)"),28) -> 28 | BX27: =BW27/SUM($BW$25:$BW$34)*100 -> 10.646388 | BY27: =BW27/$BW$4 -> 5.6
B28: 강세철 | C28: 남 | D28: =SUM(K28,Y28,AM28,BA28,BO28) -> 0 | K28: =COUNTA(G28:H28) -> 0 | Y28: =COUNTA(M28:V28) -> 0 | AM28: =COUNTA(AA28:AJ28) -> 0 | BA28: =COUNTA(AO28:AX28) -> 0 | BO28: =COUNTA(BC28:BL28) -> 0 | BV28: 12 | BW28: =IFERROR(__xludf.DUMMYFUNCTION("COUNTIF(MAP($M$8:$V$500,LAMBDA(c,IF(TRIM(c)="""","""",MIN(VALUE(SPLIT(SUBSTITUTE(SUBSTITUTE(SUBSTITUTE(c,"" "",""""),""，"","",""),"";"","",""),"","")))))),BV28)"),30) -> 30 | BX28: =BW28/SUM($BW$25:$BW$34)*100 -> 11.406844 | BY28: =BW28/$BW$4 -> 6
B29: 양정원 | C29: 여 | D29: =SUM(K29,Y29,AM29,BA29,BO29) -> 0 | K29: =COUNTA(G29:H29) -> 0 | Y29: =COUNTA(M29:V29) -> 0 | AM29: =COUNTA(AA29:AJ29) -> 0 | BA29: =COUNTA(AO29:AX29) -> 0 | BO29: =COUNTA(BC29:BL29) -> 0 | BV29: 17 | BW29: =IFERROR(__xludf.DUMMYFUNCTION("COUNTIF(MAP($M$8:$V$500,LAMBDA(c,IF(TRIM(c)="""","""",MIN(VALUE(SPLIT(SUBSTITUTE(SUBSTITUTE(SUBSTITUTE(c,"" "",""""),""，"","",""),"";"","",""),"","")))))),BV29)"),49) -> 49 | BX29: =BW29/SUM($BW$25:$BW$34)*100 -> 18.631179 | BY29: =BW29/$BW$4 -> 9.8
B30: 전다희 | C30: 여 | D30: =SUM(K30,Y30,AM30,BA30,BO30) -> 0 | K30: =COUNTA(G30:H30) -> 0 | Y30: =COUNTA(M30:V30) -> 0 | AM30: =COUNTA(AA30:AJ30) -> 0 | BA30: =COUNTA(AO30:AX30) -> 0 | BO30: =COUNTA(BC30:BL30) -> 0 | BV30: 18 | BW30: =IFERROR(__xludf.DUMMYFUNCTION("COUNTIF(MAP($M$8:$V$500,LAMBDA(c,IF(TRIM(c)="""","""",MIN(VALUE(SPLIT(SUBSTITUTE(SUBSTITUTE(SUBSTITUTE(c,"" "",""""),""，"","",""),"";"","",""),"","")))))),BV30)"),27) -> 27 | BX30: =BW30/SUM($BW$25:$BW$34)*100 -> 10.26616 | BY30: =BW30/$BW$4 -> 5.4
B31: 김혜원 | C31: 여 | D31: =SUM(K31,Y31,AM31,BA31,BO31) -> 3 | G31: 17 | I31: 11 | K31: =COUNTA(G31:H31) -> 1 | M31: 21 | U31: 18 | W31: 13 | Y31: =COUNTA(M31:V31) -> 2 | AM31: =COUNTA(AA31:AJ31) -> 0 | BA31: =COUNTA(AO31:AX31) -> 0 | BO31: =COUNTA(BC31:BL31) -> 0 | BV31: 19 | BW31: =IFERROR(__xludf.DUMMYFUNCTION("COUNTIF(MAP($M$8:$V$500,LAMBDA(c,IF(TRIM(c)="""","""",MIN(VALUE(SPLIT(SUBSTITUTE(SUBSTITUTE(SUBSTITUTE(c,"" "",""""),""，"","",""),"";"","",""),"","")))))),BV31)"),24) -> 24 | BX31: =BW31/SUM($BW$25:$BW$34)*100 -> 9.1254753 | BY31: =BW31/$BW$4 -> 4.8
B32: 김혜민 | C32: 여 | D32: =SUM(K32,Y32,AM32,BA32,BO32) -> 6 | G32: 21 | K32: =COUNTA(G32:H32) -> 1 | M32: 20 | O32: 17 | Q32: 18 | U32: 21 | Y32: =COUNTA(M32:V32) -> 4 | AA32: 21 | AM32: =COUNTA(AA32:AJ32) -> 1 | BA32: =COUNTA(AO32:AX32) -> 0 | BO32: =COUNTA(BC32:BL32) -> 0 | BV32: 20 | BW32: =IFERROR(__xludf.DUMMYFUNCTION("COUNTIF(MAP($M$8:$V$500,LAMBDA(c,IF(TRIM(c)="""","""",MIN(VALUE(SPLIT(SUBSTITUTE(SUBSTITUTE(SUBSTITUTE(c,"" "",""""),""，"","",""),"";"","",""),"","")))))),BV32)"),46) -> 46 | BX32: =BW32/SUM($BW$25:$BW$34)*100 -> 17.490494 | BY32: =BW32/$BW$4 -> 9.2
B33: 권현진 | C33: 여 | D33: =SUM(K33,Y33,AM33,BA33,BO33) -> 4 | G33: 12 | K33: =COUNTA(G33:H33) -> 1 | M33: 12 | U33: 12 | Y33: =COUNTA(M33:V33) -> 2 | AA33: 11 | AM33: =COUNTA(AA33:AJ33) -> 1 | BA33: =COUNTA(AO33:AX33) -> 0 | BO33: =COUNTA(BC33:BL33) -> 0 | BV33: 21 | BW33: =IFERROR(__xludf.DUMMYFUNCTION("COUNTIF(MAP($M$8:$V$500,LAMBDA(c,IF(TRIM(c)="""","""",MIN(VALUE(SPLIT(SUBSTITUTE(SUBSTITUTE(SUBSTITUTE(c,"" "",""""),""，"","",""),"";"","",""),"","")))))),BV33)"),33) -> 33 | BX33: =BW33/SUM($BW$25:$BW$34)*100 -> 12.547529 | BY33: =BW33/$BW$4 -> 6.6
B34: 권항주 | C34: 여 | D34: =SUM(K34,Y34,AM34,BA34,BO34) -> 5 | G34: 17 | I34: 11 | K34: =COUNTA(G34:H34) -> 1 | M34: 18 | O34: 17 | U34: 17 | W34: 13 | Y34: =COUNTA(M34:V34) -> 3 | AA34: 17 | AM34: =COUNTA(AA34:AJ34) -> 1 | BA34: =COUNTA(AO34:AX34) -> 0 | BO34: =COUNTA(BC34:BL34) -> 0
B35: 구영주 | C35: 여 | D35: =SUM(K35,Y35,AM35,BA35,BO35) -> 4 | K35: =COUNTA(G35:H35) -> 0 | O35: 17 | S35: 18 | U35: 17 | Y35: =COUNTA(M35:V35) -> 3 | AA35: 17 | AM35: =COUNTA(AA35:AJ35) -> 1 | BA35: =COUNTA(AO35:AX35) -> 0 | BO35: =COUNTA(BC35:BL35) -> 0 | BV35: 3주차
B36: 최윤정 | C36: 여 | D36: =SUM(K36,Y36,AM36,BA36,BO36) -> 4 | K36: =COUNTA(G36:H36) -> 0 | M36: 12 | Q36: 12 | U36: 17 | Y36: =COUNTA(M36:V36) -> 3 | AA36: 11 | AM36: =COUNTA(AA36:AJ36) -> 1 | BA36: =COUNTA(AO36:AX36) -> 0 | BO36: =COUNTA(BC36:BL36) -> 0 | BV36: 시간 | BW36: 출석인원 | BX36: % | BY36: 평균
B37: 김승주 | C37: 여 | D37: =SUM(K37,Y37,AM37,BA37,BO37) -> 0 | K37: =COUNTA(G37:H37) -> 0 | Y37: =COUNTA(M37:V37) -> 0 | AM37: =COUNTA(AA37:AJ37) -> 0 | BA37: =COUNTA(AO37:AX37) -> 0 | BO37: =COUNTA(BC37:BL37) -> 0 | BV37: 7 | BW37: =IFERROR(__xludf.DUMMYFUNCTION("COUNTIF(MAP($AA$8:$AJ$503,LAMBDA(c,IF(TRIM(c)="""","""",MIN(VALUE(SPLIT(SUBSTITUTE(SUBSTITUTE(SUBSTITUTE(c,"" "",""""),""，"","",""),"";"","",""),"","")))))),BV37)"),3) -> 3 | BX37: =BW37/SUM($BW$37:$BW$46)*100 -> 5.4545455 | BY37: =BW37/$BW$5 -> 0.6
B38: 신지영 | C38: 여 | D38: =SUM(K38,Y38,AM38,BA38,BO38) -> 4 | G38: 12 | K38: =COUNTA(G38:H38) -> 1 | Q38: 12 | S38: 12 | Y38: =COUNTA(M38:V38) -> 2 | AA38: 18 | AM38: =COUNTA(AA38:AJ38) -> 1 | BA38: =COUNTA(AO38:AX38) -> 0 | BO38: =COUNTA(BC38:BL38) -> 0 | BV38: 8 | BW38: =IFERROR(__xludf.DUMMYFUNCTION("COUNTIF(MAP($AA$8:$AJ$503,LAMBDA(c,IF(TRIM(c)="""","""",MIN(VALUE(SPLIT(SUBSTITUTE(SUBSTITUTE(SUBSTITUTE(c,"" "",""""),""，"","",""),"";"","",""),"","")))))),BV38)"),4) -> 4 | BX38: =BW38/SUM($BW$37:$BW$46)*100 -> 7.2727273 | BY38: =BW38/$BW$5 -> 0.8
B39: 신미화 | C39: 여 | D39: =SUM(K39,Y39,AM39,BA39,BO39) -> 4 | G39: 7 | K39: =COUNTA(G39:H39) -> 1 | M39: 7 | S39: 7 | Y39: =COUNTA(M39:V39) -> 2 | AA39: 7 | AM39: =COUNTA(AA39:AJ39) -> 1 | BA39: =COUNTA(AO39:AX39) -> 0 | BO39: =COUNTA(BC39:BL39) -> 0 | BV39: 10 | BW39: =IFERROR(__xludf.DUMMYFUNCTION("COUNTIF(MAP($AA$8:$AJ$503,LAMBDA(c,IF(TRIM(c)="""","""",MIN(VALUE(SPLIT(SUBSTITUTE(SUBSTITUTE(SUBSTITUTE(c,"" "",""""),""，"","",""),"";"","",""),"","")))))),BV39)"),10) -> 10 | BX39: =BW39/SUM($BW$37:$BW$46)*100 -> 18.181818 | BY39: =BW39/$BW$5 -> 2
B40: 박성수 | C40: 남 | D40: =SUM(K40,Y40,AM40,BA40,BO40) -> 1 | K40: =COUNTA(G40:H40) -> 0 | S40: 8 | Y40: =COUNTA(M40:V40) -> 1 | AM40: =COUNTA(AA40:AJ40) -> 0 | BA40: =COUNTA(AO40:AX40) -> 0 | BO40: =COUNTA(BC40:BL40) -> 0 | BV40: 12 | BW40: =IFERROR(__xludf.DUMMYFUNCTION("COUNTIF(MAP($AA$8:$AJ$503,LAMBDA(c,IF(TRIM(c)="""","""",MIN(VALUE(SPLIT(SUBSTITUTE(SUBSTITUTE(SUBSTITUTE(c,"" "",""""),""，"","",""),"";"","",""),"","")))))),BV40)"),0) -> 0 | BX40: =BW40/SUM($BW$37:$BW$46)*100 -> 0 | BY40: =BW40/$BW$5 -> 0
...

Sheet 25년 12월 유효회원
B2: 12월 | C2: 유효회원 | D2: 남 | E2: 여 | F2: 만료회원 | G2: 남 | H2: 여
C3: =COUNTIF($K:$K,"유효") -> 151 | D3: =COUNTIFS($K:$K,"유효",$C:$C,"남") -> 33 | E3: =COUNTIFS($K:$K,"유효",$C:$C,"여") -> 118 | F3: =COUNTIF($L:$L,"만료") -> 6 | G3: =COUNTIFS($L:$L,"만료",$C:$C,"남") -> 0 | H3: =COUNTIFS($L:$L,"만료",$C:$C,"여") -> 6
K4: 45992 | L4: 46022
B5: 이름 | C5: 성별 | D5: 전화번호 | E5: 등록 개월 | F5: 접수일 | G5: 시작일 | H5: 종료일 | I5: 출석수 | J5: 출석률 | K5: 유효회원 | L5: 만료회원 | M5: 배정선생님 | N5: 회원관리 | O5: 피트릭스 | P5: 인바디 | Q5: 1주차 | S5: 2주차 | U5: 3주차 | W5: 4주차 | Y5: 5주차
B6: 신하영 | C6: 여 | D6: 010-7406-1778 | E6: 6개월 | F6: 45834 | G6: 45951 | H6: 46162 | I6: =VLOOKUP(B6,'25년 12월 출석표'!$B$7:$D$509,3,0) -> 4 | J6: =ifna(I6/20,0) -> #NAME? | K6: =IF(AND(G6<=$L$4,H6>=$K$4),"유효","") -> 유효 | L6: =IF(AND(H6>=$K$4,H6<=$L$4),"만료","") | M6: 김효빈 | N6: FALSE | O6: FALSE | P6: FALSE | Q6: =VLOOKUP($B6,'25년 12월 출석표'!$B$2:$BQ$497,16,0)/5 -> 0.6 | S6: =VLOOKUP($B6,'25년 12월 출석표'!$B$2:$BQ$497,30,0)/5 -> 0.2 | U6: =VLOOKUP($B6,'25년 12월 출석표'!$B$2:$BQ$497,44,0)/5 -> 0 | W6: =VLOOKUP($B6,'25년 12월 출석표'!$B$2:$BQ$497,58,0)/5 -> 0 | Y6: =VLOOKUP($B6,'25년 12월 출석표'!$B$2:$BQ$503,66,0)/5 -> 0
B7: 김정숙 | C7: 여 | D7: 010-7197-6510 | E7: 6개월 | F7: 45834 | G7: 45859 | H7: 46112 | I7: =VLOOKUP(B7,'25년 12월 출석표'!$B$7:$D$509,3,0) -> 10 | J7: =ifna(I7/20,0) -> #NAME? | K7: =IF(AND(G7<=$L$4,H7>=$K$4),"유효","") -> 유효 | L7: =IF(AND(H7>=$K$4,H7<=$L$4),"만료","") | M7: 서준석 | N7: TRUE | O7: FALSE | P7: FALSE | Q7: =VLOOKUP($B7,'25년 12월 출석표'!$B$2:$BQ$497,16,0)/5 -> 0.2 | S7: =VLOOKUP($B7,'25년 12월 출석표'!$B$2:$BQ$497,30,0)/5 -> 0.4 | U7: =VLOOKUP($B7,'25년 12월 출석표'!$B$2:$BQ$497,44,0)/5 -> 0.8 | W7: =VLOOKUP($B7,'25년 12월 출석표'!$B$2:$BQ$497,58,0)/5 -> 0.2 | Y7: =VLOOKUP($B7,'25년 12월 출석표'!$B$2:$BQ$503,66,0)/5 -> 0.4
B8: 정지우 | C8: 여 | D8: 010-4703-7598 | E8: 9개월 | F8: 45834 | G8: 45962 | H8: 46249 | I8: =VLOOKUP(B8,'25년 12월 출석표'!$B$7:$D$509,3,0) -> 14 | J8: =ifna(I8/20,0) -> #NAME? | K8: =IF(AND(G8<=$L$4,H8>=$K$4),"유효","") -> 유효 | L8: =IF(AND(H8>=$K$4,H8<=$L$4),"만료","") | M8: 김효빈 | N8: FALSE | O8: FALSE | P8: FALSE | Q8: =VLOOKUP($B8,'25년 12월 출석표'!$B$2:$BQ$497,16,0)/5 -> 0.6 | S8: =VLOOKUP($B8,'25년 12월 출석표'!$B$2:$BQ$497,30,0)/5 -> 0.6 | U8: =VLOOKUP($B8,'25년 12월 출석표'!$B$2:$BQ$497,44,0)/5 -> 0.6 | W8: =VLOOKUP($B8,'25년 12월 출석표'!$B$2:$BQ$497,58,0)/5 -> 0.6 | Y8: =VLOOKUP($B8,'25년 12월 출석표'!$B$2:$BQ$503,66,0)/5 -> 0.4
B9: 임성빈 | C9: 남 | D9: 010-5238-4621 | E9: 12개월 | F9: 45835 | G9: 45859 | H9: 46223 | I9: =VLOOKUP(B9,'25년 12월 출석표'!$B$7:$D$509,3,0) -> 1 | J9: =ifna(I9/20,0) -> #NAME? | K9: =IF(AND(G9<=$L$4,H9>=$K$4),"유효","") -> 유효 | L9: =IF(AND(H9>=$K$4,H9<=$L$4),"만료","") | M9: 김효빈 | N9: FALSE | O9: FALSE | P9: FALSE | Q9: =VLOOKUP($B9,'25년 12월 출석표'!$B$2:$BQ$497,16,0)/5 -> 0 | S9: =VLOOKUP($B9,'25년 12월 출석표'!$B$2:$BQ$497,30,0)/5 -> 0 | U9: =VLOOKUP($B9,'25년 12월 출석표'!$B$2:$BQ$497,44,0)/5 -> 0 | W9: =VLOOKUP($B9,'25년 12월 출석표'!$B$2:$BQ$497,58,0)/5 -> 0.2 | Y9: =VLOOKUP($B9,'25년 12월 출석표'!$B$2:$BQ$503,66,0)/5 -> 0
B10: 곽상희 | C10: 여 | D10: 010-8751-6220 | E10: 12개월 | F10: 45835 | G10: 45946 | H10: 46223 | I10: =VLOOKUP(B10,'25년 12월 출석표'!$B$7:$D$509,3,0) -> 1 | J10: =ifna(I10/20,0) -> #NAME? | K10: =IF(AND(G10<=$L$4,H10>=$K$4),"유효","") -> 유효 | L10: =IF(AND(H10>=$K$4,H10<=$L$4),"만료","") | M10: 김효빈 | N10: FALSE | O10: FALSE | P10: FALSE | Q10: =VLOOKUP($B10,'25년 12월 출석표'!$B$2:$BQ$497,16,0)/5 -> 0 | S10: =VLOOKUP($B10,'25년 12월 출석표'!$B$2:$BQ$497,30,0)/5 -> 0 | U10: =VLOOKUP($B10,'25년 12월 출석표'!$B$2:$BQ$497,44,0)/5 -> 0 | W10: =VLOOKUP($B10,'25년 12월 출석표'!$B$2:$BQ$497,58,0)/5 -> 0.2 | Y10: =VLOOKUP($B10,'25년 12월 출석표'!$B$2:$BQ$503,66,0)/5 -> 0
B11: 이난영 | C11: 여 | D11: 010-5673-8991 | E11: 6개월 | F11: 45838 | G11: 45859 | H11: 46132 | I11: =VLOOKUP(B11,'25년 12월 출석표'!$B$7:$D$509,3,0) -> 0 | J11: =ifna(I11/20,0) -> #NAME? | K11: =IF(AND(G11<=$L$4,H11>=$K$4),"유효","") -> 유효 | L11: =IF(AND(H11>=$K$4,H11<=$L$4),"만료","") | M11: 김건 | N11: TRUE | O11: FALSE | P11: FALSE | Q11: =VLOOKUP($B11,'25년 12월 출석표'!$B$2:$BQ$497,16,0)/5 -> 0 | S11: =VLOOKUP($B11,'25년 12월 출석표'!$B$2:$BQ$497,30,0)/5 -> 0 | U11: =VLOOKUP($B11,'25년 12월 출석표'!$B$2:$BQ$497,44,0)/5 -> 0 | W11: =VLOOKUP($B11,'25년 12월 출석표'!$B$2:$BQ$497,58,0)/5 -> 0 | Y11: =VLOOKUP($B11,'25년 12월 출석표'!$B$2:$BQ$503,66,0)/5 -> 0
B12: 이지현 | C12: 여 | D12: 010-9077-6644 | E12: 12개월 | F12: 45838 | G12: 45859 | H12: 46268 | I12: =VLOOKUP(B12,'25년 12월 출석표'!$B$7:$D$509,3,0) -> 11 | J12: =ifna(I12/20,0) -> #NAME? | K12: =IF(AND(G12<=$L$4,H12>=$K$4),"유효","") -> 유효 | L12: =IF(AND(H12>=$K$4,H12<=$L$4),"만료","") | M12: 김건 | N12: TRUE | O12: FALSE | P12: FALSE | Q12: =VLOOKUP($B12,'25년 12월 출석표'!$B$2:$BQ$497,16,0)/5 -> 0.6 | S12: =VLOOKUP($B12,'25년 12월 출석표'!$B$2:$BQ$497,30,0)/5 -> 0.6 | U12: =VLOOKUP($B12,'25년 12월 출석표'!$B$2:$BQ$497,44,0)/5 -> 0.4 | W12: =VLOOKUP($B12,'25년 12월 출석표'!$B$2:$BQ$497,58,0)/5 -> 0.6 | Y12: =VLOOKUP($B12,'25년 12월 출석표'!$B$2:$BQ$503,66,0)/5 -> 0
B13: 김용희 | C13: 남 | D13: 010-2950-3381 | E13: 12개월 | F13: 45839 | G13: 45875 | H13: 46239 | I13: =VLOOKUP(B13,'25년 12월 출석표'!$B$7:$D$509,3,0) -> 0 | J13: =ifna(I13/20,0) -> #NAME? | K13: =IF(AND(G13<=$L$4,H13>=$K$4),"유효","") -> 유효 | L13: =IF(AND(H13>=$K$4,H13<=$L$4),"만료","") | M13: 김건 | N13: TRUE | O13: FALSE | P13: FALSE | Q13: =VLOOKUP($B13,'25년 12월 출석표'!$B$2:$BQ$497,16,0)/5 -> 0 | S13: =VLOOKUP($B13,'25년 12월 출석표'!$B$2:$BQ$497,30,0)/5 -> 0 | U13: =VLOOKUP($B13,'25년 12월 출석표'!$B$2:$BQ$497,44,0)/5 -> 0 | W13: =VLOOKUP($B13,'25년 12월 출석표'!$B$2:$BQ$497,58,0)/5 -> 0 | Y13: =VLOOKUP($B13,'25년 12월 출석표'!$B$2:$BQ$503,66,0)/5 -> 0
B14: 정유찬 | C14: 남 | D14: 010-5923-3791 | E14: 6개월 | F14: 45839 | G14: 45859 | H14: 46057 | I14: =VLOOKUP(B14,'25년 12월 출석표'!$B$7:$D$509,3,0) -> 3 | J14: =ifna(I14/20,0) -> #NAME? | K14: =IF(AND(G14<=$L$4,H14>=$K$4),"유효","") -> 유효 | L14: =IF(AND(H14>=$K$4,H14<=$L$4),"만료","") | M14: 김효빈 | N14: FALSE | O14: FALSE | P14: FALSE | Q14: =VLOOKUP($B14,'25년 12월 출석표'!$B$2:$BQ$497,16,0)/5 -> 0 | S14: =VLOOKUP($B14,'25년 12월 출석표'!$B$2:$BQ$497,30,0)/5 -> 0 | U14: =VLOOKUP($B14,'25년 12월 출석표'!$B$2:$BQ$497,44,0)/5 -> 0 | W14: =VLOOKUP($B14,'25년 12월 출석표'!$B$2:$BQ$497,58,0)/5 -> 0.2 | Y14: =VLOOKUP($B14,'25년 12월 출석표'!$B$2:$BQ$503,66,0)/5 -> 0.4
B15: 박유나 | C15: 여 | D15: 010-2949-9347 | E15: 12개월 | F15: 45839 | G15: 45859 | H15: 46300 | I15: =VLOOKUP(B15,'25년 12월 출석표'!$B$7:$D$509,3,0) -> 3 | J15: =ifna(I15/20,0) -> #NAME? | K15: =IF(AND(G15<=$L$4,H15>=$K$4),"유효","") -> 유효 | L15: =IF(AND(H15>=$K$4,H15<=$L$4),"만료","") | M15: 김건 | N15: TRUE | O15: FALSE | P15: FALSE | Q15: =VLOOKUP($B15,'25년 12월 출석표'!$B$2:$BQ$497,16,0)/5 -> 0 | S15: =VLOOKUP($B15,'25년 12월 출석표'!$B$2:$BQ$497,30,0)/5 -> 0.2 | U15: =VLOOKUP($B15,'25년 12월 출석표'!$B$2:$BQ$497,44,0)/5 -> 0.2 | W15: =VLOOKUP($B15,'25년 12월 출석표'!$B$2:$BQ$497,58,0)/5 -> 0.2 | Y15: =VLOOKUP($B15,'25년 12월 출석표'!$B$2:$BQ$503,66,0)/5 -> 0
B16: 황서영 | C16: 여 | D16: 010-5457-5827 | E16: 12개월 | F16: 45839 | G16: 45859 | H16: 46240 | I16: =VLOOKUP(B16,'25년 12월 출석표'!$B$7:$D$509,3,0) -> 8 | J16: =ifna(I16/20,0) -> #NAME? | K16: =IF(AND(G16<=$L$4,H16>=$K$4),"유효","") -> 유효 | L16: =IF(AND(H16>=$K$4,H16<=$L$4),"만료","") | M16: 김건 | N16: TRUE | O16: FALSE | P16: FALSE | Q16: =VLOOKUP($B16,'25년 12월 출석표'!$B$2:$BQ$497,16,0)/5 -> 0.6 | S16: =VLOOKUP($B16,'25년 12월 출석표'!$B$2:$BQ$497,30,0)/5 -> 0.6 | U16: =VLOOKUP($B16,'25년 12월 출석표'!$B$2:$BQ$497,44,0)/5 -> 0.2 | W16: =VLOOKUP($B16,'25년 12월 출석표'!$B$2:$BQ$497,58,0)/5 -> 0.2 | Y16: =VLOOKUP($B16,'25년 12월 출석표'!$B$2:$BQ$503,66,0)/5 -> 0
B17: 김지윤 | C17: 여 | D17: 010-4032-8075 | E17: 12개월 | F17: 45839 | G17: 45859 | H17: 46325 | I17: =VLOOKUP(B17,'25년 12월 출석표'!$B$7:$D$509,3,0) -> 8 | J17: =ifna(I17/20,0) -> #NAME? | K17: =IF(AND(G17<=$L$4,H17>=$K$4),"유효","") -> 유효 | L17: =IF(AND(H17>=$K$4,H17<=$L$4),"만료","") | M17: 김효빈 | N17: FALSE | O17: FALSE | P17: FALSE | Q17: =VLOOKUP($B17,'25년 12월 출석표'!$B$2:$BQ$497,16,0)/5 -> 0.4 | S17: =VLOOKUP($B17,'25년 12월 출석표'!$B$2:$BQ$497,30,0)/5 -> 0.2 | U17: =VLOOKUP($B17,'25년 12월 출석표'!$B$2:$BQ$497,44,0)/5 -> 0.4 | W17: =VLOOKUP($B17,'25년 12월 출석표'!$B$2:$BQ$497,58,0)/5 -> 0.4 | Y17: =VLOOKUP($B17,'25년 12월 출석표'!$B$2:$BQ$503,66,0)/5 -> 0.2
... B83: 최라인 | C83: 여 | D83: 010-5104-7266 | E83: 12개월 | F83: 45915 | G83: 45917 | H83: 46304 | I83: =VLOOKUP(B83,'25년 12월 출석표'!$B$7:$D$509,3,0) -> 6 | J83: =ifna(I83/20,0) -> #NAME? | K83: =IF(AND(G83<=$L$4,H83>=$K$4),"유효","") -> 유효 | L83: =IF(AND(H83>=$K$4,H83<=$L$4),"만료","") | M83: 김건 | N83: TRUE | O83: FALSE | P83: FALSE | Q83: =VLOOKUP($B83,'25년 12월 출석표'!$B$2:$BQ$497,16,0)/5 -> 0 | S83: =VLOOKUP($B83,'25년 12월 출석표'!$B$2:$BQ$497,30,0)/5 -> 0.6 | U83: =VLOOKUP($B83,'25년 12월 출석표'!$B$2:$BQ$497,44,0)/5 -> 0.4 | W83: =VLOOKUP($B83,'25년 12월 출석표'!$B$2:$BQ$497,58,0)/5 -> 0.2 | Y83: =VLOOKUP($B83,'25년 12월 출석표'!$B$2:$BQ$503,66,0)/5 -> 0
B84: 진성훈 | C84: 남 | D84: 010-5092-5399 | E84: 7개월 | F84: 45917 | G84: 45943 | H84: 46154 | I84: =VLOOKUP(B84,'25년 12월 출석표'!$B$7:$D$509,3,0) -> 6 | J84: =ifna(I84/20,0) -> #NAME? | K84: =IF(AND(G84<=$L$4,H84>=$K$4),"유효","") -> 유효 | L84: =IF(AND(H84>=$K$4,H84<=$L$4),"만료","") | N84: FALSE | O84: FALSE | P84: FALSE | Q84: =VLOOKUP($B84,'25년 12월 출석표'!$B$2:$BQ$497,16,0)/5 -> 0.2 | S84: =VLOOKUP($B84,'25년 12월 출석표'!$B$2:$BQ$497,30,0)/5 -> 0.6 | U84: =VLOOKUP($B84,'25년 12월 출석표'!$B$2:$BQ$497,44,0)/5 -> 0.2 | W84: =VLOOKUP($B84,'25년 12월 출석표'!$B$2:$BQ$497,58,0)/5 -> 0.2 | Y84: =VLOOKUP($B84,'25년 12월 출석표'!$B$2:$BQ$503,66,0)/5 -> 0
B85: 우정원 | C85: 여 | D85: 010-0000-0000 | E85: 7개월 | F85: 45917 | G85: 45943 | H85: 46154 | I85: =VLOOKUP(B85,'25년 12월 출석표'!$B$7:$D$509,3,0) -> 8 | J85: =ifna(I85/20,0) -> #NAME? | K85: =IF(AND(G85<=$L$4,H85>=$K$4),"유효","") -> 유효 | L85: =IF(AND(H85>=$K$4,H85<=$L$4),"만료","") | M85: 김건 | N85: TRUE | O85: FALSE | P85: FALSE | Q85: =VLOOKUP($B85,'25년 12월 출석표'!$B$2:$BQ$497,16,0)/5 -> 0.4 | S85: =VLOOKUP($B85,'25년 12월 출석표'!$B$2:$BQ$497,30,0)/5 -> 0.6 | U85: =VLOOKUP($B85,'25년 12월 출석표'!$B$2:$BQ$497,44,0)/5 -> 0.4 | W85: =VLOOKUP($B85,'25년 12월 출석표'!$B$2:$BQ$497,58,0)/5 -> 0.2 | Y85: =VLOOKUP($B85,'25년 12월 출석표'!$B$2:$BQ$503,66,0)/5 -> 0
B86: 장진영 | C86: 여 | D86: 010-8930-7966 | E86: 9개월 | F86: 45918 | G86: 45919 | H86: 46191 | I86: =VLOOKUP(B86,'25년 12월 출석표'!$B$7:$D$509,3,0) -> 0 | J86: =ifna(I86/20,0) -> #NAME? | K86: =IF(AND(G86<=$L$4,H86>=$K$4),"유효","") -> 유효 | L86: =IF(AND(H86>=$K$4,H86<=$L$4),"만료","") | M86: 김효빈 | N86: FALSE | O86: FALSE | P86: FALSE | Q86: =VLOOKUP($B86,'25년 12월 출석표'!$B$2:$BQ$497,16,0)/5 -> 0 | S86: =VLOOKUP($B86,'25년 12월 출석표'!$B$2:$BQ$497,30,0)/5 -> 0 | U86: =VLOOKUP($B86,'25년 12월 출석표'!$B$2:$BQ$497,44,0)/5 -> 0 | W86: =VLOOKUP($B86,'25년 12월 출석표'!$B$2:$BQ$497,58,0)/5 -> 0 | Y86: =VLOOKUP($B86,'25년 12월 출석표'!$B$2:$BQ$503,66,0)/5 -> 0
B87: 김수진 | C87: 여 | D87: 010-2563-1076 | E87: 9개월 | F87: 45918 | G87: 45919 | H87: 46042 | I87: =VLOOKUP(B87,'25년 12월 출석표'!$B$7:$D$509,3,0) -> 7 | J87: =ifna(I87/20,0) -> #NAME? | K87: =IF(AND(G87<=$L$4,H87>=$K$4),"유효","") -> 유효 | L87: =IF(AND(H87>=$K$4,H87<=$L$4),"만료","") | M87: 김건 | N87: TRUE | O87: FALSE | P87: FALSE | Q87: =VLOOKUP($B87,'25년 12월 출석표'!$B$2:$BQ$497,16,0)/5 -> 0.6 | S87: =VLOOKUP($B87,'25년 12월 출석표'!$B$2:$BQ$497,30,0)/5 -> 0.4 | U87: =VLOOKUP($B87,'25년 12월 출석표'!$B$2:$BQ$497,44,0)/5 -> 0 | W87: =VLOOKUP($B87,'25년 12월 출석표'!$B$2:$BQ$497,58,0)/5 -> 0.2 | Y87: =VLOOKUP($B87,'25년 12월 출석표'!$B$2:$BQ$503,66,0)/5 -> 0.2
B88: 권은주 | C88: 여 | D88: 010-5226-3575 | E88: 12개월 | F88: 45920 | G88: 45922 | H88: 46286 | I88: =VLOOKUP(B88,'25년 12월 출석표'!$B$7:$D$509,3,0) -> 4 | J88: =ifna(I88/20,0) -> #NAME? | K88: =IF(AND(G88<=$L$4,H88>=$K$4),"유효","") -> 유효 | L88: =IF(AND(H88>=$K$4,H88<=$L$4),"만료","") | M88: 김효빈 | N88: FALSE | O88: FALSE | P88: FALSE | Q88: =VLOOKUP($B88,'25년 12월 출석표'!$B$2:$BQ$497,16,0)/5 -> 0 | S88: =VLOOKUP($B88,'25년 12월 출석표'!$B$2:$BQ$497,30,0)/5 -> 0.4 | U88: =VLOOKUP($B88,'25년 12월 출석표'!$B$2:$BQ$497,44,0)/5 -> 0.2 | W88: =VLOOKUP($B88,'25년 12월 출석표'!$B$2:$BQ$497,58,0)/5 -> 0.2 | Y88: =VLOOKUP($B88,'25년 12월 출석표'!$B$2:$BQ$503,66,0)/5 -> 0
B89: 권기훈 | C89: 남 | D89: 010-2112-5879 | E89: 8개월 | F89: 45924 | G89: 45950 | H89: 46241 | I89: =VLOOKUP(B89,'25년 12월 출석표'!$B$7:$D$509,3,0) -> 0 | J89: =ifna(I89/20,0) -> #NAME? | K89: =IF(AND(G89<=$L$4,H89>=$K$4),"유효","") -> 유효 | L89: =IF(AND(H89>=$K$4,H89<=$L$4),"만료","") | M89: 김효빈 | N89: FALSE | O89: FALSE | P89: FALSE | Q89: =VLOOKUP($B89,'25년 12월 출석표'!$B$2:$BQ$497,16,0)/5 -> 0 | S89: =VLOOKUP($B89,'25년 12월 출석표'!$B$2:$BQ$497,30,0)/5 -> 0 | U89: =VLOOKUP($B89,'25년 12월 출석표'!$B$2:$BQ$497,44,0)/5 -> 0 | W89: =VLOOKUP($B89,'25년 12월 출석표'!$B$2:$BQ$497,58,0)/5 -> 0 | Y89: =VLOOKUP($B89,'25년 12월 출석표'!$B$2:$BQ$503,66,0)/5 -> 0
B90: 이유빈 | C90: 여 | D90: 010-2706-3001 | E90: 6개월 | F90: 45924 | G90: 45974 | H90: 46154 | I90: =VLOOKUP(B90,'25년 12월 출석표'!$B$7:$D$509,3,0) -> 2 | J90: =ifna(I90/20,0) -> #NAME? | K90: =IF(AND(G90<=$L$4,H90>=$K$4),"유효","") -> 유효 | L90: =IF(AND(H90>=$K$4,H90<=$L$4),"만료","") | M90: 김효빈 | N90: FALSE | O90: FALSE | P90: FALSE | Q90: =VLOOKUP($B90,'25년 12월 출석표'!$B$2:$BQ$497,16,0)/5 -> 0.2 | S90: =VLOOKUP($B90,'25년 12월 출석표'!$B$2:$BQ$497,30,0)/5 -> 0.2 | U90: =VLOOKUP($B90,'25년 12월 출석표'!$B$2:$BQ$497,44,0)/5 -> 0 | W90: =VLOOKUP($B90,'25년 12월 출석표'!$B$2:$BQ$497,58,0)/5 -> 0 | Y90: =VLOOKUP($B90,'25년 12월 출석표'!$B$2:$BQ$503,66,0)/5 -> 0
B91: 윤태종 | C91: 남 | D91: 010-2542-9131 | E91: 3개월 | F91: 45925 | G91: 45940 | H91: 46093 | I91: =VLOOKUP(B91,'25년 12월 출석표'!$B$7:$D$509,3,0) -> 0 | J91: =ifna(I91/20,0) -> #NAME? | K91: =IF(AND(G91<=$L$4,H91>=$K$4),"유효","") -> 유효 | L91: =IF(AND(H91>=$K$4,H91<=$L$4),"만료","") | M91: 김효빈 | N91: FALSE | O91: FALSE | P91: FALSE | Q91: =VLOOKUP($B91,'25년 12월 출석표'!$B$2:$BQ$497,16,0)/5 -> 0 | S91: =VLOOKUP($B91,'25년 12월 출석표'!$B$2:$BQ$497,30,0)/5 -> 0 | U91: =VLOOKUP($B91,'25년 12월 출석표'!$B$2:$BQ$497,44,0)/5 -> 0 | W91: =VLOOKUP($B91,'25년 12월 출석표'!$B$2:$BQ$497,58,0)/5 -> 0 | Y91: =VLOOKUP($B91,'25년 12월 출석표'!$B$2:$BQ$503,66,0)/5 -> 0
B92: 박혜진 | C92: 여 | D92: 010-3342-9343 | E92: 3개월 | F92: 45925 | G92: 45945 | H92: 46067 | I92: =VLOOKUP(B92,'25년 12월 출석표'!$B$7:$D$509,3,0) -> 4 | J92: =ifna(I92/20,0) -> #NAME? | K92: =IF(AND(G92<=$L$4,H92>=$K$4),"유효","") -> 유효 | L92: =IF(AND(H92>=$K$4,H92<=$L$4),"만료","") | M92: 김효빈 | N92: FALSE | O92: FALSE | P92: FALSE | Q92: =VLOOKUP($B92,'25년 12월 출석표'!$B$2:$BQ$497,16,0)/5 -> 0.4 | S92: =VLOOKUP($B92,'25년 12월 출석표'!$B$2:$BQ$497,30,0)/5 -> 0.2 | U92: =VLOOKUP($B92,'25년 12월 출석표'!$B$2:$BQ$497,44,0)/5 -> 0 | W92: =VLOOKUP($B92,'25년 12월 출석표'!$B$2:$BQ$497,58,0)/5 -> 0 | Y92: =VLOOKUP($B92,'25년 12월 출석표'!$B$2:$BQ$503,66,0)/5 -> 0.2
B93: 김설리 | C93: 여 | D93: 010-2498-9516 | E93: 6개월 | F93: 45927 | G93: 45940 | H93: 46274 | I93: =VLOOKUP(B93,'25년 12월 출석표'!$B$7:$D$509,3,0) -> 0 | J93: =ifna(I93/20,0) -> #NAME? | K93: =IF(AND(G93<=$L$4,H93>=$K$4),"유효","") -> 유효 | L93: =IF(AND(H93>=$K$4,H93<=$L$4),"만료","") | M93: 김건 | N93: TRUE | O93: TRUE | P93: FALSE | Q93: =VLOOKUP($B93,'25년 12월 출석표'!$B$2:$BQ$497,16,0)/5 -> 0 | S93: =VLOOKUP($B93,'25년 12월 출석표'!$B$2:$BQ$497,30,0)/5 -> 0 | U93: =VLOOKUP($B93,'25년 12월 출석표'!$B$2:$BQ$497,44,0)/5 -> 0 | W93: =VLOOKUP($B93,'25년 12월 출석표'!$B$2:$BQ$497,58,0)/5 -> 0 | Y93: =VLOOKUP($B93,'25년 12월 출석표'!$B$2:$BQ$503,66,0)/5 -> 0
